Workbook

Sheet MONITORING
A1: MONITORING SHEET FOR MACHINERIES, INDUSTRIAL EQUIPMENT, OTHER SERVICES
A2: Seven-Trent Machineries Industrial Equipment Trading
A3: Starting March 10, 2026
D5: =SUM(D8:D1048576) -> 5478579.9
A6: DATE OF PAYMENT | B6: TR NO: | C6: AR No: | D6: AMOUNT COLLECTED | E6: JOURNAL ENTRY SECTION | I6: CUSTOMER DETAILS | M6: PRODUCT / SERVICES DETAIL | R6: SEGMENT | S6: DR NO. / SOA REF. | T6: DR DATE / SOA DATE | U6: DATE OF REVERSAL OF ENTRY / RECOGNITION OF INCOME
E7: CODE | F7: GENERAL LEDGER (Dr.) | G7: COA | H7: GENERAL LEDGER COA (Cr.) | I7: CODE | J7: CUSTOMER | K7: CONTACT PERSON | L7: ADDRESS | M7: CODE | N7: PRODUCTS / SERVICES | O7: QTY | P7: BRAND / TYPE | Q7: OTHER DESCRIPTION ( ELABORATE DETAILS )
A8: 46091 | B8: 632 | C8: 2026-921 | D8: 2850 | E8: RCS | F8: =IF(E8<>"",VLOOKUP(E8,CODE!$B$2:$C$11,2,0),"") -> RCBC -SAVINGS | G8: 43016 | H8: =IF(G8<>"",VLOOKUP(G8,COA!$A$3:$G$1048576,2,0),"") -> Job Orders | I8: Basagan | J8: =IF(I8<>"",VLOOKUP(I8,'CUSTOMER LISTS'!$B$3:$E$1048576,2,0),"") -> RJM GASOLINAHAN PETROCHEMICAL PRODUCTS TRADING | K8: =IF(I8<>"",VLOOKUP(I8,'CUSTOMER LISTS'!$B$3:$E$1048576,3,0),"") -> FELICISIMA PANTORILLA ORILLAN | L8: =IF(I8<>"",VLOOKUP(I8,'CUSTOMER LISTS'!$B$3:$E$1048576,4,0),"") -> BRGY. BASAGAN, KATIPUNAN, ZAMBOANGA DEL NORTE | M8: 721 | N8: =IF(M8<>"",VLOOKUP(M8,'PRODUCT & SERVICES'!$O:$P,2,0),"") -> Job Order | Q8: REPLACEMENT OF RELAY & CHECK-UP | R8: OPS | S8: NA | T8: NA
A9: 46091 | B9: 632 | C9: 2026-921 | D9: 500 | E9: PSS | F9: =IF(E9<>"",VLOOKUP(E9,CODE!$B$2:$C$11,2,0),"") -> PSBC- SAVINGS | G9: 21016 | H9: =IF(G9<>"",VLOOKUP(G9,COA!$A$3:$G$1048576,2,0),"") -> Unearned Revenue - OPS | I9: Basagan | J9: =IF(I9<>"",VLOOKUP(I9,'CUSTOMER LISTS'!$B$3:$E$1048576,2,0),"") -> RJM GASOLINAHAN PETROCHEMICAL PRODUCTS TRADING | K9: =IF(I9<>"",VLOOKUP(I9,'CUSTOMER LISTS'!$B$3:$E$1048576,3,0),"") -> FELICISIMA PANTORILLA ORILLAN | L9: =IF(I9<>"",VLOOKUP(I9,'CUSTOMER LISTS'!$B$3:$E$1048576,4,0),"") -> BRGY. BASAGAN, KATIPUNAN, ZAMBOANGA DEL NORTE | M9: 731 | N9: =IF(M9<>"",VLOOKUP(M9,'PRODUCT & SERVICES'!$O:$P,2,0),"") -> Other OPS ( Pls. Specify ) | Q9: PAYMENT FOR LEAKED BUCKET
A10: 46091 | B10: 633 | C10: 2026-922 | D10: 1300 | E10: PSS | F10: =IF(E10<>"",VLOOKUP(E10,CODE!$B$2:$C$11,2,0),"") -> PSBC- SAVINGS | G10: 21016 | H10: =IF(G10<>"",VLOOKUP(G10,COA!$A$3:$G$1048576,2,0),"") -> Unearned Revenue - OPS | I10: Singaran | J10: =IF(I10<>"",VLOOKUP(I10,'CUSTOMER LISTS'!$B$3:$E$1048576,2,0),"") -> ED-ZEL FUEL REFILLING STATION | K10: =IF(I10<>"",VLOOKUP(I10,'CUSTOMER LISTS'!$B$3:$E$1048576,3,0),"") -> HAZEL NAMIT CABOVERDE | L10: =IF(I10<>"",VLOOKUP(I10,'CUSTOMER LISTS'!$B$3:$E$1048576,4,0),"") -> BRGY. SINGARAN, LA LIBERTAD, ZAMBOANGA DEL NORTE | M10: 731 | N10: =IF(M10<>"",VLOOKUP(M10,'PRODUCT & SERVICES'!$O:$P,2,0),"") -> Other OPS ( Pls. Specify ) | Q10: RECALIBRATION | R10: OPS | S10: 2026-00108
A11: 46092 | B11: 634 | C11: 2026-923 | D11: 2350 | E11: PSS | F11: =IF(E11<>"",VLOOKUP(E11,CODE!$B$2:$C$11,2,0),"") -> PSBC- SAVINGS | G11: 21016 | H11: =IF(G11<>"",VLOOKUP(G11,COA!$A$3:$G$1048576,2,0),"") -> Unearned Revenue - OPS | I11: Lingasad | J11: =IF(I11<>"",VLOOKUP(I11,'CUSTOMER LISTS'!$B$3:$E$1048576,2,0),"") -> ARQUIZA FUEL REFILLING STATION | K11: =IF(I11<>"",VLOOKUP(I11,'CUSTOMER LISTS'!$B$3:$E$1048576,3,0),"") -> ANTONIO MANINGO ARQUIZA | L11: =IF(I11<>"",VLOOKUP(I11,'CUSTOMER LISTS'!$B$3:$E$1048576,4,0),"") -> BRGY. LINGASAD, POLANCO, ZAMBOANGA DEL NORTE | M11: 711 | N11: =IF(M11<>"",VLOOKUP(M11,'PRODUCT & SERVICES'!$O:$P,2,0),"") -> National | O11: 1 BOX | P11: 2T 200ML X 60 | Q11: FULL PAYMENT ON PURCHASED ITEM | R11: OPS | S11: 2026-031 | T11: 46093
A12: 46093 | B12: 635 | C12: 2026-924 | D12: 20050 | E12: PNC | F12: =IF(E12<>"",VLOOKUP(E12,CODE!$B$2:$C$11,2,0),"") -> PNB - CHECKING | G12: 65000 | H12: =IF(G12<>"",VLOOKUP(G12,COA!$A$3:$G$1048576,2,0),"") -> Miscellaneous Expenses_DHPP | I12: OTHER CUSTOMER | J12: =IF(I12<>"",VLOOKUP(I12,'CUSTOMER LISTS'!$B$3:$E$1048576,2,0),"") -> JOHN BILLY CONCHE | K12: =IF(I12<>"",VLOOKUP(I12,'CUSTOMER LISTS'!$B$3:$E$1048576,3,0),"") -> JOHN BILLY CONCHE | L12: =IF(I12<>"",VLOOKUP(I12,'CUSTOMER LISTS'!$B$3:$E$1048576,4,0),"") -> BRGY. STA.ISABEL, DIPOLOG CITY | M12: 761 | N12: =IF(M12<>"",VLOOKUP(M12,'PRODUCT & SERVICES'!$O:$P,2,0),"") -> Others ( Pls. Specify ) | Q12: PAYMENT FOR CASH IN PNB TO GCASH - CHARGED AS MISCELLANEOUS EXPENSE UPON PAYMENT
A13: 46093 | B13: 636 | C13: 2026-925 | D13: 457200 | E13: EWC | F13: =IF(E13<>"",VLOOKUP(E13,CODE!$B$2:$C$11,2,0),"") -> EASTWEST-CHECKING | H13: =IF(G13<>"",VLOOKUP(G13,COA!$A$3:$G$1048576,2,0),"") | J13: =IF(I13<>"",VLOOKUP(I13,'CUSTOMER LISTS'!$B$3:$E$1048576,2,0),"") | K13: =IF(I13<>"",VLOOKUP(I13,'CUSTOMER LISTS'!$B$3:$E$1048576,3,0),"") | L13: =IF(I13<>"",VLOOKUP(I13,'CUSTOMER LISTS'!$B$3:$E$1048576,4,0),"") | M13: 761 | N13: =IF(M13<>"",VLOOKUP(M13,'PRODUCT & SERVICES'!$O:$P,2,0),"") -> Others ( Pls. Specify ) | Q13: CANCELLED TRANSACTION / CANCELLED ACKNOWLEDGMENT RECEIPT- ERROR ISSUANCE
A14: 46094 | B14: 637 | C14: 2026-926 | D14: 8000 | E14: MBC | F14: =IF(E14<>"",VLOOKUP(E14,CODE!$B$2:$C$11,2,0),"") -> METROBANK-CHECKING | G14: 12070 | H14: =IF(G14<>"",VLOOKUP(G14,COA!$A$3:$G$1048576,2,0),"") -> Advances to Employees - DHPP | I14: CNR | J14: =IF(I14<>"",VLOOKUP(I14,'CUSTOMER LISTS'!$B$3:$E$1048576,2,0),"") -> CLYDE N. REBOLLOS | K14: =IF(I14<>"",VLOOKUP(I14,'CUSTOMER LISTS'!$B$3:$E$1048576,3,0),"") -> CLYDE N. REBOLLOS | L14: =IF(I14<>"",VLOOKUP(I14,'CUSTOMER LISTS'!$B$3:$E$1048576,4,0),"") -> BRGY. STA.ISABEL, DIPOLOG CITY | M14: 761 | N14: =IF(M14<>"",VLOOKUP(M14,'PRODUCT & SERVICES'!$O:$P,2,0),"") -> Others ( Pls. Specify ) | Q14: SALARY LOAN
A15: 46094 | B15: 638 | C15: 2026-927 | D15: 425 | E15: MBC | F15: =IF(E15<>"",VLOOKUP(E15,CODE!$B$2:$C$11,2,0),"") -> METROBANK-CHECKING | G15: 20000 | H15: =IF(G15<>"",VLOOKUP(G15,COA!$A$3:$G$1048576,2,0),"") -> A/Payables - Current - DHPP | J15: =IF(I15<>"",VLOOKUP(I15,'CUSTOMER LISTS'!$B$3:$E$1048576,2,0),"") | K15: =IF(I15<>"",VLOOKUP(I15,'CUSTOMER LISTS'!$B$3:$E$1048576,3,0),"") | L15: =IF(I15<>"",VLOOKUP(I15,'CUSTOMER LISTS'!$B$3:$E$1048576,4,0),"") | M15: 761 | N15: =IF(M15<>"",VLOOKUP(M15,'PRODUCT & SERVICES'!$O:$P,2,0),"") -> Others ( Pls. Specify ) | Q15: CANCELLED TRANSACTION / CANCELLED ACKNOWLEDGMENT RECEIPT- ERROR ISSUANCE
A16: 46094 | B16: 639 | C16: 2026-928 | D16: 30378.29 | E16: PNC | F16: =IF(E16<>"",VLOOKUP(E16,CODE!$B$2:$C$11,2,0),"") -> PNB - CHECKING | G16: 15000 | H16: =IF(G16<>"",VLOOKUP(G16,COA!$A$3:$G$1048576,2,0),"") -> Due from STPC - DHPP | I16: STPC-San Pedro | J16: =IF(I16<>"",VLOOKUP(I16,'CUSTOMER LISTS'!$B$3:$E$1048576,2,0),"") -> SEVEN-TRENT PETROLEUM CORP. | K16: =IF(I16<>"",VLOOKUP(I16,'CUSTOMER LISTS'!$B$3:$E$1048576,3,0),"") -> SEVEN-TRENT PETROLEUM CORP. | L16: =IF(I16<>"",VLOOKUP(I16,'CUSTOMER LISTS'!$B$3:$E$1048576,4,0),"") -> BRGY. SAN PEDRO, DAPITAN, ZAMBOANGA DEL NORTE | M16: 761 | N16: =IF(M16<>"",VLOOKUP(M16,'PRODUCT & SERVICES'!$O:$P,2,0),"") -> Others ( Pls. Specify ) | Q16: COLLECTION OF RECEIVABLES - PAYMENT FOR VARIOUS EXPENSES FOR MAY 1-31, 2025
A17: 46094 | B17: 640 | C17: 2026-929 | D17: 500000 | E17: EWC | F17: =IF(E17<>"",VLOOKUP(E17,CODE!$B$2:$C$11,2,0),"") -> EASTWEST-CHECKING | G17: 25500 | H17: =IF(G17<>"",VLOOKUP(G17,COA!$A$3:$G$1048576,2,0),"") -> Other Payables_Current - DHPP | I17: STPC-San Pedro | J17: =IF(I17<>"",VLOOKUP(I17,'CUSTOMER LISTS'!$B$3:$E$1048576,2,0),"") -> SEVEN-TRENT PETROLEUM CORP. | K17: =IF(I17<>"",VLOOKUP(I17,'CUSTOMER LISTS'!$B$3:$E$1048576,3,0),"") -> SEVEN-TRENT PETROLEUM CORP. | L17: =IF(I17<>"",VLOOKUP(I17,'CUSTOMER LISTS'!$B$3:$E$1048576,4,0),"") -> BRGY. SAN PEDRO, DAPITAN, ZAMBOANGA DEL NORTE | M17: 761 | N17: =IF(M17<>"",VLOOKUP(M17,'PRODUCT & SERVICES'!$O:$P,2,0),"") -> Others ( Pls. Specify ) | Q17: RECOGNIZED SHORT TERM LOAN
A18: 46095 | B18: 641 | C18: 2026-930 | D18: 400000 | E18: EWC | F18: =IF(E18<>"",VLOOKUP(E18,CODE!$B$2:$C$11,2,0),"") -> EASTWEST-CHECKING | G18: 21023 | H18: =IF(G18<>"",VLOOKUP(G18,COA!$A$3:$G$1048576,2,0),"") -> Unearned Revenue - DMIE | I18: TM-CALAMBA | J18: =IF(I18<>"",VLOOKUP(I18,'CUSTOMER LISTS'!$B$3:$E$1048576,2,0),"") -> TM'S GAS REFILLING STATION | K18: =IF(I18<>"",VLOOKUP(I18,'CUSTOMER LISTS'!$B$3:$E$1048576,3,0),"") -> ISABELO A. VILLANUEVA III | L18: =IF(I18<>"",VLOOKUP(I18,'CUSTOMER LISTS'!$B$3:$E$1048576,4,0),"") -> BRGY. SOUTHWESTERN POBLACION, CALAMBA, MISAMIS OCCIDENTAL | M18: 2217 | N18: =IF(M18<>"",VLOOKUP(M18,'PRODUCT & SERVICES'!$O:$P,2,0),"") -> 5.0 KL TSRO Standard Machine | Q18: DOWNPAYMENT FOR 5 KL TSRO STP MACHINE
A19: 46097 | B19: 642 | C19: 2026-931 | D19: 250 | E19: PSS | F19: =IF(E19<>"",VLOOKUP(E19,CODE!$B$2:$C$11,2,0),"") -> PSBC- SAVINGS | G19: 21016 | H19: =IF(G19<>"",VLOOKUP(G19,COA!$A$3:$G$1048576,2,0),"") -> Unearned Revenue - OPS | I19: Singaran | J19: =IF(I19<>"",VLOOKUP(I19,'CUSTOMER LISTS'!$B$3:$E$1048576,2,0),"") -> ED-ZEL FUEL REFILLING STATION | K19: =IF(I19<>"",VLOOKUP(I19,'CUSTOMER LISTS'!$B$3:$E$1048576,3,0),"") -> HAZEL NAMIT CABOVERDE | L19: =IF(I19<>"",VLOOKUP(I19,'CUSTOMER LISTS'!$B$3:$E$1048576,4,0),"") -> BRGY. SINGARAN, LA LIBERTAD, ZAMBOANGA DEL NORTE | M19: 731 | N19: =IF(M19<>"",VLOOKUP(M19,'PRODUCT & SERVICES'!$O:$P,2,0),"") -> Other OPS ( Pls. Specify ) | Q19: PAYMENT FOR NOZZLE JACKET
A20: 46097 | B20: 643 | C20: 2026-932 | D20: 12647 | E20: EWC | F20: =IF(E20<>"",VLOOKUP(E20,CODE!$B$2:$C$11,2,0),"") -> EASTWEST-CHECKING | G20: 25506 | H20: =IF(G20<>"",VLOOKUP(G20,COA!$A$3:$G$1048576,2,0),"") -> Other Payables_Current - OPS | I20: STPC-San Pedro | J20: =IF(I20<>"",VLOOKUP(I20,'CUSTOMER LISTS'!$B$3:$E$1048576,2,0),"") -> SEVEN-TRENT PETROLEUM CORP. | K20: =IF(I20<>"",VLOOKUP(I20,'CUSTOMER LISTS'!$B$3:$E$1048576,3,0),"") -> SEVEN-TRENT PETROLEUM CORP. | L20: =IF(I20<>"",VLOOKUP(I20,'CUSTOMER LISTS'!$B$3:$E$1048576,4,0),"") -> BRGY. SAN PEDRO, DAPITAN, ZAMBOANGA DEL NORTE | M20: 761 | N20: =IF(M20<>"",VLOOKUP(M20,'PRODUCT & SERVICES'!$O:$P,2,0),"") -> Others ( Pls. Specify ) | Q20: TAMARAW AMORTIZATION
A21: 46100 | B21: 644 | C21: 2026-933 | D21: 4260 | E21: PSS | F21: =IF(E21<>"",VLOOKUP(E21,CODE!$B$2:$C$11,2,0),"") -> PSBC- SAVINGS | G21: 21016 | H21: =IF(G21<>"",VLOOKUP(G21,COA!$A$3:$G$1048576,2,0),"") -> Unearned Revenue - OPS | I21: Dansulyan-Awa | J21: =IF(I21<>"",VLOOKUP(I21,'CUSTOMER LISTS'!$B$3:$E$1048576,2,0),"") -> MJ FUEL REFILLING STATION | K21: =IF(I21<>"",VLOOKUP(I21,'CUSTOMER LISTS'!$B$3:$E$1048576,3,0),"") -> JERELYN MONTEZA AWA | L21: =IF(I21<>"",VLOOKUP(I21,'CUSTOMER LISTS'!$B$3:$E$1048576,4,0),"") -> BRGY. DANSULLAN, POLANCO, ZAMBOANGA DEL NORTE | M21: 731 | N21: =IF(M21<>"",VLOOKUP(M21,'PRODUCT & SERVICES'!$O:$P,2,0),"") -> Other OPS ( Pls. Specify ) | O21: 1 BOX | P21: DEOMAX 15W-40 OIL | Q21: FULL PAYMENT ON PURCHASED ITEM | R21: OPS | S21: 2026-037 | T21: 46100
A22: 46100 | B22: 645 | C22: 2026-934 | D22: 48653.97 | E22: PNC | F22: =IF(E22<>"",VLOOKUP(E22,CODE!$B$2:$C$11,2,0),"") -> PNB - CHECKING | G22: 15000 | H22: =IF(G22<>"",VLOOKUP(G22,COA!$A$3:$G$1048576,2,0),"") -> Due from STPC - DHPP | I22: STPC-San Pedro | J22: =IF(I22<>"",VLOOKUP(I22,'CUSTOMER LISTS'!$B$3:$E$1048576,2,0),"") -> SEVEN-TRENT PETROLEUM CORP. | K22: =IF(I22<>"",VLOOKUP(I22,'CUSTOMER LISTS'!$B$3:$E$1048576,3,0),"") -> SEVEN-TRENT PETROLEUM CORP. | L22: =IF(I22<>"",VLOOKUP(I22,'CUSTOMER LISTS'!$B$3:$E$1048576,4,0),"") -> BRGY. SAN PEDRO, DAPITAN, ZAMBOANGA DEL NORTE | M22: 761 | N22: =IF(M22<>"",VLOOKUP(M22,'PRODUCT & SERVICES'!$O:$P,2,0),"") -> Others ( Pls. Specify ) | Q22: PAYMENT FOR BIR DOCUMENTATION TAX STAMP
A23: 46100 | B23: 646 | C23: 2026-935 | D23: 18890 | E23: FVC | F23: =IF(E23<>"",VLOOKUP(E23,CODE!$B$2:$C$11,2,0),"") -> FIRST VALLEY -CHECKING | G23: 43026 | H23: =IF(G23<>"",VLOOKUP(G23,COA!$A$3:$G$1048576,2,0),"") -> Service Income | I23: Suertes-Guitran | J23: =IF(I23<>"",VLOOKUP(I23,'CUSTOMER LISTS'!$B$3:$E$1048576,2,0),"") -> SUERTE GAS STATION | K23: =IF(I23<>"",VLOOKUP(I23,'CUSTOMER LISTS'!$B$3:$E$1048576,3,0),"") -> ALJUN LATA SUERTE | L23: =IF(I23<>"",VLOOKUP(I23,'CUSTOMER LISTS'!$B$3:$E$1048576,4,0),"") -> BRGY. GUITRAN, DUMINGAG, ZAMBOANGA DEL SUR | M23: 751 | N23: =IF(M23<>"",VLOOKUP(M23,'PRODUCT & SERVICES'!$O:$P,2,0),"") -> Other Services ( Pls. Specify ) | Q23: COC PROCESSING
A24: 46101 | B24: 647 | C24: 2026-936 | D24: 5300 | E24: PNC | F24: =IF(E24<>"",VLOOKUP(E24,CODE!$B$2:$C$11,2,0),"") -> PNB - CHECKING | G24: 21023 | H24: =IF(G24<>"",VLOOKUP(G24,COA!$A$3:$G$1048576,2,0),"") -> Unearned Revenue - DMIE | I24: MUTIA-OROQUIETA | J24: =IF(I24<>"",VLOOKUP(I24,'CUSTOMER LISTS'!$B$3:$E$1048576,2,0),"") -> MUTIA RANGERS FUEL RETAILING | K24: =IF(I24<>"",VLOOKUP(I24,'CUSTOMER LISTS'!$B$3:$E$1048576,3,0),"") -> JULIE ANN CONING MUTIA | L24: =IF(I24<>"",VLOOKUP(I24,'CUSTOMER LISTS'!$B$3:$E$1048576,4,0),"") -> BRGY. DOLIPOS, BAJO, OROQUIETA CITY | M24: 731 | N24: =IF(M24<>"",VLOOKUP(M24,'PRODUCT & SERVICES'!$O:$P,2,0),"") -> Other OPS ( Pls. Specify ) | Q24: CALIBRATION BUCKET | R24: OPS | S24: 2026-00107 | T24: 46218
A25: 46102 | B25: 648 | C25: 2026-937 | D25: 200000 | E25: MBC | F25: =IF(E25<>"",VLOOKUP(E25,CODE!$B$2:$C$11,2,0),"") -> METROBANK-CHECKING | G25: 21023 | H25: =IF(G25<>"",VLOOKUP(G25,COA!$A$3:$G$1048576,2,0),"") -> Unearned Revenue - DMIE | I25: Villaflor Oroquieta | J25: =IF(I25<>"",VLOOKUP(I25,'CUSTOMER LISTS'!$B$3:$E$1048576,2,0),"") -> AYA G MICRO GAS STATION | K25: =IF(I25<>"",VLOOKUP(I25,'CUSTOMER LISTS'!$B$3:$E$1048576,3,0),"") -> ARTIUS TALADUA GALINDO | L25: =IF(I25<>"",VLOOKUP(I25,'CUSTOMER LISTS'!$B$3:$E$1048576,4,0),"") -> BRGY. VILLAFLOR, OROQUIETA CITY, MISAMIS OCCIDENTAL | M25: 2218 | N25: =IF(M25<>"",VLOOKUP(M25,'PRODUCT & SERVICES'!$O:$P,2,0),"") -> 5.0 KL TSRO Standing Machine | Q25: ADDITIONAL PAYMENT (PROMO PRICE ON MACHINE) | S25: 2026-0009 | T25: 4/7/2026
A26: 46104 | B26: 649 | C26: 2026-938 | D26: 2350 | E26: PNC | F26: =IF(E26<>"",VLOOKUP(E26,CODE!$B$2:$C$11,2,0),"") -> PNB - CHECKING | G26: 21016 | H26: =IF(G26<>"",VLOOKUP(G26,COA!$A$3:$G$1048576,2,0),"") -> Unearned Revenue - OPS | I26: Binoni | J26: =IF(I26<>"",VLOOKUP(I26,'CUSTOMER LISTS'!$B$3:$E$1048576,2,0),"") -> BOY G FUEL REFILLING STATION | K26: =IF(I26<>"",VLOOKUP(I26,'CUSTOMER LISTS'!$B$3:$E$1048576,3,0),"") -> EPIFRAS RUDAS GALLEPOSO | L26: =IF(I26<>"",VLOOKUP(I26,'CUSTOMER LISTS'!$B$3:$E$1048576,4,0),"") -> BRGY. BINONI, SALUG, ZAMBOANGA DEL NORTE | M26: 712 | N26: =IF(M26<>"",VLOOKUP(M26,'PRODUCT & SERVICES'!$O:$P,2,0),"") -> Sea-Oil | O26: 1 BOX | P26: 2T 200ML X 60 | Q26: FULL PAYMENT ON PURCHASED ITEM | S26: 2026-0036 | T26: 3/26/2026
A27: 46104 | B27: 650 | C27: 2026-939 | D27: 173500 | E27: MBC | F27: =IF(E27<>"",VLOOKUP(E27,CODE!$B$2:$C$11,2,0),"") -> METROBANK-CHECKING | G27: 21023 | H27: =IF(G27<>"",VLOOKUP(G27,COA!$A$3:$G$1048576,2,0),"") -> Unearned Revenue - DMIE | I27: Villaflor Oroquieta | J27: =IF(I27<>"",VLOOKUP(I27,'CUSTOMER LISTS'!$B$3:$E$1048576,2,0),"") -> AYA G MICRO GAS STATION | K27: =IF(I27<>"",VLOOKUP(I27,'CUSTOMER LISTS'!$B$3:$E$1048576,3,0),"") -> ARTIUS TALADUA GALINDO | L27: =IF(I27<>"",VLOOKUP(I27,'CUSTOMER LISTS'!$B$3:$E$1048576,4,0),"") -> BRGY. VILLAFLOR, OROQUIETA CITY, MISAMIS OCCIDENTAL | M27: 2218 | N27: =IF(M27<>"",VLOOKUP(M27,'PRODUCT & SERVICES'!$O:$P,2,0),"") -> 5.0 KL TSRO Standing Machine | Q27: FULL PAYMENT ON 5 KL MACHINE (PROMO PRICE) | S27: 2026-0009 | T27: 4/7/2026
A28: 46106 | B28: 651 | C28: 2026-940 | D28: 2400 | E28: PSC | F28: =IF(E28<>"",VLOOKUP(E28,CODE!$B$2:$C$11,2,0),"") -> PSBC - CHECKING | G28: 21016 | H28: =IF(G28<>"",VLOOKUP(G28,COA!$A$3:$G$1048576,2,0),"") -> Unearned Revenue - OPS | I28: Dansulyan-Awa | J28: =IF(I28<>"",VLOOKUP(I28,'CUSTOMER LISTS'!$B$3:$E$1048576,2,0),"") -> MJ FUEL REFILLING STATION | K28: =IF(I28<>"",VLOOKUP(I28,'CUSTOMER LISTS'!$B$3:$E$1048576,3,0),"") -> JERELYN MONTEZA AWA | L28: =IF(I28<>"",VLOOKUP(I28,'CUSTOMER LISTS'!$B$3:$E$1048576,4,0),"") -> BRGY. DANSULLAN, POLANCO, ZAMBOANGA DEL NORTE | M28: 712 | N28: =IF(M28<>"",VLOOKUP(M28,'PRODUCT & SERVICES'!$O:$P,2,0),"") -> Sea-Oil | O28: 1 BOX | P28: 2T 200ML X 60 | Q28: FULL PAYMENT ON PURCHASED ITEM | S28: 2026-049 | T28: 46106
A29: 04/01/2026 | B29: 652 | C29: 2026-941 | D29: 1500 | E29: RCS | F29: =IF(E29<>"",VLOOKUP(E29,CODE!$B$2:$C$11,2,0),"") -> RCBC -SAVINGS | G29: 43016 | H29: =IF(G29<>"",VLOOKUP(G29,COA!$A$3:$G$1048576,2,0),"") -> Job Orders | I29: Bayog buboan | J29: =IF(I29<>"",VLOOKUP(I29,'CUSTOMER LISTS'!$B$3:$E$1048576,2,0),"") -> REDBAR GAS REFILLING STATION | K29: =IF(I29<>"",VLOOKUP(I29,'CUSTOMER LISTS'!$B$3:$E$1048576,3,0),"") -> ARNEL GAJO ENTAG | L29: =IF(I29<>"",VLOOKUP(I29,'CUSTOMER LISTS'!$B$3:$E$1048576,4,0),"") -> BRGY. BOBUAN, BAYOG, ZAMBOANGA DEL SUR | M29: 721 | N29: =IF(M29<>"",VLOOKUP(M29,'PRODUCT & SERVICES'!$O:$P,2,0),"") -> Job Order | Q29: CALIBRATION | U29: 04/01/2026
A30: 04/01/2026 | B30: 653 | C30: 2026-942 | D30: 1500 | E30: RCS | F30: =IF(E30<>"",VLOOKUP(E30,CODE!$B$2:$C$11,2,0),"") -> RCBC -SAVINGS | G30: 43016 | H30: =IF(G30<>"",VLOOKUP(G30,COA!$A$3:$G$1048576,2,0),"") -> Job Orders | I30: Liba Bayog | J30: =IF(I30<>"",VLOOKUP(I30,'CUSTOMER LISTS'!$B$3:$E$1048576,2,0),"") -> KELTEX GAS REFILLING STATION | K30: =IF(I30<>"",VLOOKUP(I30,'CUSTOMER LISTS'!$B$3:$E$1048576,3,0),"") -> LOVELY BERNARDO FABIANTES | L30: =IF(I30<>"",VLOOKUP(I30,'CUSTOMER LISTS'!$B$3:$E$1048576,4,0),"") -> BRGY. LIBA, BAYOG, ZAMBOANGA DEL SUR | M30: 721 | N30: =IF(M30<>"",VLOOKUP(M30,'PRODUCT & SERVICES'!$O:$P,2,0),"") -> Job Order | Q30: CALIBRATION | U30: 04/01/2026
A31: 04/01/2026 | B31: 654 | C31: 2026-943 | D31: 4000 | E31: RCS | F31: =IF(E31<>"",VLOOKUP(E31,CODE!$B$2:$C$11,2,0),"") -> RCBC -SAVINGS | G31: 43016 | H31: =IF(G31<>"",VLOOKUP(G31,COA!$A$3:$G$1048576,2,0),"") -> Job Orders | I31: Bayog Bulilit | J31: =IF(I31<>"",VLOOKUP(I31,'CUSTOMER LISTS'!$B$3:$E$1048576,2,0),"") -> JDM-6 FUEL STATION | K31: =IF(I31<>"",VLOOKUP(I31,'CUSTOMER LISTS'!$B$3:$E$1048576,3,0),"") -> DELIA SAJULGA BACO | L31: =IF(I31<>"",VLOOKUP(I31,'CUSTOMER LISTS'!$B$3:$E$1048576,4,0),"") -> BRGY. KAHAYAGAN, BAYOG, ZAMBOANGA DEL SUR | M31: 721 | N31: =IF(M31<>"",VLOOKUP(M31,'PRODUCT & SERVICES'!$O:$P,2,0),"") -> Job Order | Q31: CALIBRATION | U31: 04/01/2026
A32: 04/01/2026 | B32: 655 | C32: 2026-944 | D32: 1500 | E32: RCS | F32: =IF(E32<>"",VLOOKUP(E32,CODE!$B$2:$C$11,2,0),"") -> RCBC -SAVINGS | G32: 43016 | H32: =IF(G32<>"",VLOOKUP(G32,COA!$A$3:$G$1048576,2,0),"") -> Job Orders | I32: Dipili Bayog | J32: =IF(I32<>"",VLOOKUP(I32,'CUSTOMER LISTS'!$B$3:$E$1048576,2,0),"") -> MG'S FUEL REFILLING STATION | K32: =IF(I32<>"",VLOOKUP(I32,'CUSTOMER LISTS'!$B$3:$E$1048576,3,0),"") -> NORMITA DELA CERNA | L32: =IF(I32<>"",VLOOKUP(I32,'CUSTOMER LISTS'!$B$3:$E$1048576,4,0),"") -> BRGY. DIPILI, BAYOG, ZAMBOANGA DEL SUR | M32: 721 | N32: =IF(M32<>"",VLOOKUP(M32,'PRODUCT & SERVICES'!$O:$P,2,0),"") -> Job Order | Q32: CALIBRATION | U32: 04/01/2026
A33: 04/01/2026 | B33: 656 | C33: 2026-945 | D33: 4800 | E33: PSS | F33: =IF(E33<>"",VLOOKUP(E33,CODE!$B$2:$C$11,2,0),"") -> PSBC- SAVINGS | G33: 21016 | H33: =IF(G33<>"",VLOOKUP(G33,COA!$A$3:$G$1048576,2,0),"") -> Unearned Revenue - OPS | I33: Villahermosa | J33: =IF(I33<>"",VLOOKUP(I33,'CUSTOMER LISTS'!$B$3:$E$1048576,2,0),"") -> CM-POWER FUEL REFILLING STATION | K33: =IF(I33<>"",VLOOKUP(I33,'CUSTOMER LISTS'!$B$3:$E$1048576,3,0),"") -> CHARLENE ESTRADA MANDANTES | L33: =IF(I33<>"",VLOOKUP(I33,'CUSTOMER LISTS'!$B$3:$E$1048576,4,0),"") -> BRGY. VILLAHERMOSA, POLANCO, ZAMBOANGA DEL NORTE | M33: 712 | N33: =IF(M33<>"",VLOOKUP(M33,'PRODUCT & SERVICES'!$O:$P,2,0),"") -> Sea-Oil | O33: 2 BOXES | P33: 2T 200ML X 60 | Q33: FULL PAYMENT ON PURCHASED ITEM | R33: OPS | S33: 2026-045 | T33: 46118
A34: 04/06/2026 | B34: 657 | C34: 2026-946 | D34: 1300 | E34: PSS | F34: =IF(E34<>"",VLOOKUP(E34,CODE!$B$2:$C$11,2,0),"") -> PSBC- SAVINGS | G34: 21016 | H34: =IF(G34<>"",VLOOKUP(G34,COA!$A$3:$G$1048576,2,0),"") -> Unearned Revenue - OPS | I34: Paruk Siay | J34: =IF(I34<>"",VLOOKUP(I34,'CUSTOMER LISTS'!$B$3:$E$1048576,2,0),"") -> CRILOUR FUEL REFILLING STATION | K34: =IF(I34<>"",VLOOKUP(I34,'CUSTOMER LISTS'!$B$3:$E$1048576,3,0),"") -> ELSON ENRIQUEZ BASCO | L34: =IF(I34<>"",VLOOKUP(I34,'CUSTOMER LISTS'!$B$3:$E$1048576,4,0),"") -> BRGY. PARUK, SIAY, ZAMBOANGA SIBUGAY | M34: 731 | N34: =IF(M34<>"",VLOOKUP(M34,'PRODUCT & SERVICES'!$O:$P,2,0),"") -> Other OPS ( Pls. Specify ) | Q34: RECALIBRATION
A35: 04/07/2026 | B35: 658 | C35: 2026-947 | D35: 93900 | E35: MBC | F35: =IF(E35<>"",VLOOKUP(E35,CODE!$B$2:$C$11,2,0),"") -> METROBANK-CHECKING | G35: 25500 | H35: =IF(G35<>"",VLOOKUP(G35,COA!$A$3:$G$1048576,2,0),"") -> Other Payables_Current - DHPP | I35: STPC-San Pedro | J35: =IF(I35<>"",VLOOKUP(I35,'CUSTOMER LISTS'!$B$3:$E$1048576,2,0),"") -> SEVEN-TRENT PETROLEUM CORP. | K35: =IF(I35<>"",VLOOKUP(I35,'CUSTOMER LISTS'!$B$3:$E$1048576,3,0),"") -> SEVEN-TRENT PETROLEUM CORP. | L35: =IF(I35<>"",VLOOKUP(I35,'CUSTOMER LISTS'!$B$3:$E$1048576,4,0),"") -> BRGY. SAN PEDRO, DAPITAN, ZAMBOANGA DEL NORTE | M35: 761 | N35: =IF(M35<>"",VLOOKUP(M35,'PRODUCT & SERVICES'!$O:$P,2,0),"") -> Others ( Pls. Specify ) | Q35: SHORT TERM LOAN
A36: 04/07/2026 | B36: 659 | C36: 2026-948 | D36: 50000 | E36: MBC | F36: =IF(E36<>"",VLOOKUP(E36,CODE!$B$2:$C$11,2,0),"") -> METROBANK-CHECKING | G36: 43060 | H36: =IF(G36<>"",VLOOKUP(G36,COA!$A$3:$G$1048576,2,0),"") -> Miscellaneous Income - DHPP | I36: E.TAN | J36: =IF(I36<>"",VLOOKUP(I36,'CUSTOMER LISTS'!$B$3:$E$1048576,2,0),"") -> MEM TRADING AND HAULING SERVICES INC. | K36: =IF(I36<>"",VLOOKUP(I36,'CUSTOMER LISTS'!$B$3:$E$1048576,3,0),"") -> EMMANUEL TAN | L36: =IF(I36<>"",VLOOKUP(I36,'CUSTOMER LISTS'!$B$3:$E$1048576,4,0),"") -> BRGY. SOUTHWESTERN POBLACION, CALAMBA, MISAMIS OCCIDENTAL | M36: 761 | N36: =IF(M36<>"",VLOOKUP(M36,'PRODUCT & SERVICES'!$O:$P,2,0),"") -> Others ( Pls. Specify ) | Q36: FUEL ASSISTANCE INCOME
A37: 04/08/2026 | B37: 660 | C37: 2026-949 | D37: 35210 | E37: MBC | F37: =IF(E37<>"",VLOOKUP(E37,CODE!$B$2:$C$11,2,0),"") -> METROBANK-CHECKING | G37: 21023 | H37: =IF(G37<>"",VLOOKUP(G37,COA!$A$3:$G$1048576,2,0),"") -> Unearned Revenue - DMIE | I37: Villaflor Oroquieta | J37: =IF(I37<>"",VLOOKUP(I37,'CUSTOMER LISTS'!$B$3:$E$1048576,2,0),"") -> AYA G MICRO GAS STATION | K37: =IF(I37<>"",VLOOKUP(I37,'CUSTOMER LISTS'!$B$3:$E$1048576,3,0),"") -> ARTIUS TALADUA GALINDO | L37: =IF(I37<>"",VLOOKUP(I37,'CUSTOMER LISTS'!$B$3:$E$1048576,4,0),"") -> BRGY. VILLAFLOR, OROQUIETA CITY, MISAMIS OCCIDENTAL | M37: 761 | N37: =IF(M37<>"",VLOOKUP(M37,'PRODUCT & SERVICES'!$O:$P,2,0),"") -> Others ( Pls. Specify ) | Q37: SHIPPING PARTICIPATION
A38: 04/08/2026 | B38: 661 | C38: 2026-950 | D38: 35210 | E38: EWC | F38: =IF(E38<>"",VLOOKUP(E38,CODE!$B$2:$C$11,2,0),"") -> EASTWEST-CHECKING | G38: 21023 | H38: =IF(G38<>"",VLOOKUP(G38,COA!$A$3:$G$1048576,2,0),"") -> Unearned Revenue - DMIE | I38: MUTIA-OROQUIETA | J38: =IF(I38<>"",VLOOKUP(I38,'CUSTOMER LISTS'!$B$3:$E$1048576,2,0),"") -> MUTIA RANGERS FUEL RETAILING | K38: =IF(I38<>"",VLOOKUP(I38,'CUSTOMER LISTS'!$B$3:$E$1048576,3,0),"") -> JULIE ANN CONING MUTIA | L38: =IF(I38<>"",VLOOKUP(I38,'CUSTOMER LISTS'!$B$3:$E$1048576,4,0),"") -> BRGY. DOLIPOS, BAJO, OROQUIETA CITY | M38: 761 | N38: =IF(M38<>"",VLOOKUP(M38,'PRODUCT & SERVICES'!$O:$P,2,0),"") -> Others ( Pls. Specify ) | Q38: SHIPPING PARTICIPATION | R38: DMIE
A39: 04/09/2026 | B39: 662 | C39: 2026-951 | D39: 2200 | E39: PSC | F39: =IF(E39<>"",VLOOKUP(E39,CODE!$B$2:$C$11,2,0),"") -> PSBC - CHECKING | G39: 21016 | H39: =IF(G39<>"",VLOOKUP(G39,COA!$A$3:$G$1048576,2,0),"") -> Unearned Revenue - OPS | I39: CALAMBA | J39: =IF(I39<>"",VLOOKUP(I39,'CUSTOMER LISTS'!$B$3:$E$1048576,2,0),"") -> CALAMBA FUEL REFILLING STATION | K39: =IF(I39<>"",VLOOKUP(I39,'CUSTOMER LISTS'!$B$3:$E$1048576,3,0),"") -> RONAN CASTILLON | L39: =IF(I39<>"",VLOOKUP(I39,'CUSTOMER LISTS'!$B$3:$E$1048576,4,0),"") -> BRGY. MAGCAMIGUING, CALAMBA, ZAMBOANGA DEL NORTE | M39: 711 | N39: =IF(M39<>"",VLOOKUP(M39,'PRODUCT & SERVICES'!$O:$P,2,0),"") -> National | O39: 1/2 BOX | P39: 2T 1L X 24 | Q39: FULL PAYMENT ON PURCHASED ITEM | S39: 2026-046 | T39: 4/10/2026
A40: 04/09/2026 | B40: 662 | C40: 2026-951 | D40: 2125 | E40: PSC | F40: =IF(E40<>"",VLOOKUP(E40,CODE!$B$2:$C$11,2,0),"") -> PSBC - CHECKING | G40: 21016 | H40: =IF(G40<>"",VLOOKUP(G40,COA!$A$3:$G$1048576,2,0),"") -> Unearned Revenue - OPS | I40: CALAMBA | J40: =IF(I40<>"",VLOOKUP(I40,'CUSTOMER LISTS'!$B$3:$E$1048576,2,0),"") -> CALAMBA FUEL REFILLING STATION | K40: =IF(I40<>"",VLOOKUP(I40,'CUSTOMER LISTS'!$B$3:$E$1048576,3,0),"") -> RONAN CASTILLON | L40: =IF(I40<>"",VLOOKUP(I40,'CUSTOMER LISTS'!$B$3:$E$1048576,4,0),"") -> BRGY. MAGCAMIGUING, CALAMBA, ZAMBOANGA DEL NORTE | M40: 712 | N40: =IF(M40<>"",VLOOKUP(M40,'PRODUCT & SERVICES'!$O:$P,2,0),"") -> Sea-Oil | O40: 1/2 BOX | P40: 2T 1L X 24 | Q40: FULL PAYMENT ON PURCHASED ITEM | S40: 2026-046 | T40: 4/10/2026
A41: 04/11/2026 | B41: 663 | C41: 2026-952 | D41: 1400 | E41: PSC | F41: =IF(E41<>"",VLOOKUP(E41,CODE!$B$2:$C$11,2,0),"") -> PSBC - CHECKING | G41: 21016 | H41: =IF(G41<>"",VLOOKUP(G41,COA!$A$3:$G$1048576,2,0),"") -> Unearned Revenue - OPS | I41: New Sicayab | J41: =IF(I41<>"",VLOOKUP(I41,'CUSTOMER LISTS'!$B$3:$E$1048576,2,0),"") -> FAME GAS REFILLING STATION | K41: =IF(I41<>"",VLOOKUP(I41,'CUSTOMER LISTS'!$B$3:$E$1048576,3,0),"") -> FERNANDO DELA ROSA PARAN | L41: =IF(I41<>"",VLOOKUP(I41,'CUSTOMER LISTS'!$B$3:$E$1048576,4,0),"") -> BRGY. NEW SICAYAB, POLANCO, ZAMBOANGA DEL NORTE | M41: 761 | N41: =IF(M41<>"",VLOOKUP(M41,'PRODUCT & SERVICES'!$O:$P,2,0),"") -> Others ( Pls. Specify ) | Q41: RECALIBRATION
...

Sheet CUSTOMER LISTS
B2: CODING (FROM OPERATIONS) | C2: REGISTERED BUSINESS NAME | D2: SUPPLIER'S NAME | E2: BUSINESS ADDRESS
B3: Bacong bulilit | C3: HI-LAND FUEL REFILLING STATION | D3: SITTI MAIRA LANGAN ANDAL | E3: BRGY. BACONG, SALUG, ZAMBONGA DEL NORTE
B4: Aseniero | C4: IAP'S GASOLINE STATION | D4: ALLAN FEROLINO OBAS | E4: BRGY. ASENIERO, DAPITAN, ZAMBOANGA DEL NORTE
B5: Bacong Pamil | C5: MJ FUEL REFILLING STATION | D5: MERCEDARIO NUGAS PAMIL | E5: BRGY. BACONG, SALUG, ZAMBONGA DEL NORTE
B6: Bago
B7: Bagumbang palomar
B8: Bajo Oroqueita | C8: NONON'S FUEL STATION | D8: CRISAN SABIJON HERNANE | E8: BRGY. SAN VICENTE BAJO, OROQUIETA CITY, MISAMIS OCCIDENTAL
B9: Balagon Siay | C9: VASH FUEL REFILLING STATION | D9: JHOANNE SHANE MARIE ESMORES AGLOBO | E9: BRGY. BALAGON, SIAY, ZAMBOANGA SIBUGAY
B10: Balamban Mahayag | C10: MMN GAS STATION | D10: MARY JANE RESILOSA PAUSANOS | E10: BRGY. BAG-ONG BALAMBAN, MAHAYAG, ZAMBOANGA DEL SUR
B11: Barcelona
B12: Basagan | C12: RJM GASOLINAHAN PETROCHEMICAL PRODUCTS TRADING | D12: FELICISIMA PANTORILLA ORILLAN | E12: BRGY. BASAGAN, KATIPUNAN, ZAMBOANGA DEL NORTE
B13: Bato Plaridel | C13: MARCUS FUEL STATION | D13: MARICRIS FE MAGHINAY ARANDID | E13: BRGY. BATO, PLARIDEL, MISAMIS OCCIDENTAL
B14: Baylimango | C14: MORTE FUEL REFILLING STATION | D14: PRIMITIVO ALICMAN MORTE | E14: BRGY. BAYLIMANGO, DAPITAN CITY, ZAMBOANGA DEL NORTE
B15: Bayog (BACO) | C15: JD-MACS GAS REFILLING STATION | D15: DELIA S. BACO | E15: BRGY. KAHAYAGAN, BAYOG, ZAMBOANGA DEL SUR
B16: Bayog buboan | C16: REDBAR GAS REFILLING STATION | D16: ARNEL GAJO ENTAG | E16: BRGY. BOBUAN, BAYOG, ZAMBOANGA DEL SUR
B17: Bayog Bulilit | C17: JDM-6 FUEL STATION | D17: DELIA SAJULGA BACO | E17: BRGY. KAHAYAGAN, BAYOG, ZAMBOANGA DEL SUR
B18: Binoni | C18: BOY G FUEL REFILLING STATION | D18: EPIFRAS RUDAS GALLEPOSO | E18: BRGY. BINONI, SALUG, ZAMBOANGA DEL NORTE
B19: Bucana Siocon | C19: NAUFAR FUEL REFILLING STATION | D19: JULCARIM ALVAREZ CASALIN | E19: BRGY. BUCANA, SIOCON, ZAMBOANGA DEL NORTE
B20: Buug
B21: Calican | C21: FOUR ANGELS FUEL REFILLING STATION | D21: FREMIE ALFON PALCONAYO | E21: BRGY. CALICAN, PIÑAN, ZAMBOANGA DEL NORTE
B22: Caracol Salug | C22: AZ FUEL REFILLING STATION | D22: SALAHUDDIN AKIL HAMBALI | E22: BRGY. CARACOL, SALUG, ZAMBOANGA DEL NORTE
B23: Clarin Settlement | C23: COUNTRYROAD FUEL REFILLING STATION | D23: ASHLEY NICOLE REAMBONANZA LLERIN | E23: BRGY. CLARIN SETTLEMENT, OROQUIETA CITY, MISAMIS OCCIDENTAL
B24: Cogon | C24: DJ FUEL REFILLING STATION | D24: DAPHNE CLAIRE ABARCA MARQUINA | E24: BRGY. COGON, DIPOLOG CITY, ZAMBOANGA DEL NORTE
B25: Coloran Siay | C25: LIA-FRAN-LILY FUEL STATION | D25: LILIA CAMBE UNITO | E25: BRGY. COLORAN, SIAY, ZAMBOANGA DEL SUR
B26: Dampalan (Osmena)
B27: Dampalan DAPITAN | C27: RAMAD FUEL REFILLING STATION | D27: RAMIL QUIGUING ADANTE | E27: BRGY. DAMPALAN, DAPITAN CITY, ZAMBOANGA DEL NORTE
B28: Dansulyan | C28: GD FUEL REFILLING STATION | D28: DOUET PEPITO AMARILLE | E28: BRGY. DANSULLAN, POLANCO, ZAMBOANGA DEL NORTE
B29: Del Pilar | C29: ARLEGUI FUEL REFILLING STATION | D29: SANDY LOU TRANSMIL ARLEGUI | E29: BRGY. DEL PILAR, PIÑAN, ZAMBOANGA DEL NORTE
B30: Dona Josefa | C30: PATRICK & BRYLE FUEL REFILLING STATION | D30: BOB DALMAN PAGENTE | E30: BRGY. DOÑA JOSEFA, SINDANGAN, ZAMBOANGA DEL NORTE
B31: Denuyan siayan
B32: Detulan | C32: B & J GAS REFILLING STATION | D32: ISAGANI BARAZON LEDESMA | E32: BRGY. DITULAN, DUMINGAG, ZAMBOANGA DEL SUR
B33: Dicayo | C33: MJ HABAGAT GAS STATION | D33: THERESA MEE SARENAS HABAGAT | E33: BRGY. DAANGLUNGSOD, KATIPUNAN, ZAMBOANGA DEL NORTE
B34: Dicoyong | C34: PIPZ GAS REFILLING STATION | D34: JEMWEL TAMAN ZAMORA | E34: BRGY. DICOYONG, SINDANGAN, ZAMBOANGA DEL NORTE
B35: Dilawa | C35: G-P GAS REFILLING STATION | D35: JAYNALYN GUIO PACAÑA | E35: BRGY. DILAWA, PIÑAN, ZAMBOANGA DEL NORTE
B36: Dinasan | C36: JRG GAS REFILLING STATION | D36: JUDY ASISTER GONDULA | E36: BRGY. DINASAN, JOSE DALMAN, ZAMBOANGA DEL NORTE
B37: Dohinob | C37: LJ GAS REFILLING STATION | D37: LEONARDO BAYBAY UGNIT III | E37: BRGY. DOHINOB, PRES. MANUEL A. ROXAS, ZAMBOANGA DEL NORTE
B38: Don Vic Dennis | C38: 3DS & B GAS REFILLING STATION | D38: DENNIS RAMIREZ DELOS SANTOS | E38: BRGY. TUNO, DON VICTORIANO, MISAMIS OCCIDENTAL
B39: Dumingag Bulilit | C39: K2J2 GAS REFILLING STATION | D39: JENIE FE BALOGBOG ALINSUG | E39: BRGY. SAN PEDRO, DUMINGAG, ZAMBOANGA DEL SUR
B40: Eunice
B41: Fatima Liloy | C41: ENCAR GASOLINE STATION | D41: REY ENRICO ORIOLA EROY | E41: BRGY. FATIMA, LILOY, ZAMBOANGA DEL NORTE
...

Sheet PRODUCT & SERVICES
B1: DIRECTORY | O1: CODING
B4: 1. Fuel Products | G4: Fuel
B5: 1.1 | C5: Gasoline
C6: 111 | D6: Premium (RON95) | O6: =C6 -> 111 | P6: =D6 -> Premium (RON95) | Q6: DHPP
C7: 112 | D7: Regular (RON 91) | O7: =C7 -> 112 | P7: =D7 -> Regular (RON 91) | Q7: DHPP
B8: 1.2 | C8: Diesel
C9: 121 | D9: Diesel ( Krudo ) | O9: =C9 -> 121 | P9: =D9 -> Diesel ( Krudo ) | Q9: DHPP
B10: 1.3 | C10: Jet Fuel
C11: 131 | D11: Jet Fuel | O11: =C11 -> 131 | P11: =D11 -> Jet Fuel | Q11: DHPP
B12: 1.4 | C12: LPG
C13: 141 | O13: =C13 -> 141 | Q13: DHPP
C14: 142 | O14: =C14 -> 142 | Q14: DHPP
C15: 143 | O15: =C15 -> 143 | Q15: DHPP
C16: 144 | O16: =C16 -> 144 | Q16: DHPP
B17: 1.5 | C17: Kerosene
C18: 151 | O18: =C18 -> 151 | Q18: DHPP
B20: 2. Storage & Handling Equipment | J20: CATEGORY
C21: 2.1 | D21: Tanks & Containers
D22: 211 | E22: Storage tanks | O22: =D22 -> 211 | P22: =E22 -> Storage tanks | Q22: DMIE
D23: 212 | E23: Barrels / Drums | O23: =D23 -> 212 | P23: =E23 -> Barrels / Drums | Q23: DMIE
C24: 2.2 | D24: Dispensing Equipment
D25: 2.2.1 | E25: Fuel Dispensers
E26: 2211 | F26: 1.5 KL TSRO Standard Machine | J26: MFS | O26: =E26 -> 2211 | P26: =F26 -> 1.5 KL TSRO Standard Machine | Q26: DMIE
E27: 2212 | F27: 1.5 KL TSRO Standing Machine | J27: MFS | O27: =E27 -> 2212 | P27: =F27 -> 1.5 KL TSRO Standing Machine | Q27: DMIE
E28: 2213 | F28: 2.0 KL TSRO Standard Machine | J28: MFS | O28: =E28 -> 2213 | P28: =F28 -> 2.0 KL TSRO Standard Machine | Q28: DMIE
E29: 2214 | F29: 2.0 KL TSRO Standing Machine | J29: MFS | O29: =E29 -> 2214 | P29: =F29 -> 2.0 KL TSRO Standing Machine | Q29: DMIE
E30: 2215 | F30: 3.0 KL TSRO Standard Machine | J30: MFS | O30: =E30 -> 2215 | P30: =F30 -> 3.0 KL TSRO Standard Machine | Q30: DMIE
E31: 2216 | F31: 3.0 KL TSRO Standing Machine | J31: MFS | O31: =E31 -> 2216 | P31: =F31 -> 3.0 KL TSRO Standing Machine | Q31: DMIE
E32: 2217 | F32: 5.0 KL TSRO Standard Machine | J32: MFS | O32: =E32 -> 2217 | P32: =F32 -> 5.0 KL TSRO Standard Machine | Q32: DMIE
E33: 2218 | F33: 5.0 KL TSRO Standing Machine | J33: MFS | O33: =E33 -> 2218 | P33: =F33 -> 5.0 KL TSRO Standing Machine | Q33: DMIE
E34: 2219 | F34: 6.0 KL TSRO Standard Machine | J34: MFS | O34: =E34 -> 2219 | P34: =F34 -> 6.0 KL TSRO Standard Machine | Q34: DMIE
E35: 2220 | F35: 6.0 KL TSRO Standing Machine | J35: MFS | O35: =E35 -> 2220 | P35: =F35 -> 6.0 KL TSRO Standing Machine | Q35: DMIE
D37: 2.2.2 | E37: Fuel Dispenser Parts
E38: 2221 | F38: Transfer Pump | O38: =E38 -> 2221 | P38: =F38 -> Transfer Pump | Q38: DMIE
E39: 2222 | F39: Hose | O39: =E39 -> 2222 | P39: =F39 -> Hose | Q39: DMIE
E40: 2223 | F40: Nozzle | O40: =E40 -> 2223 | P40: =F40 -> Nozzle | Q40: DMIE
E41: 2224 | F41: Keypad | O41: =E41 -> 2224 | P41: =F41 -> Keypad | Q41: DMIE
E42: 2225 | F42: Display | O42: =E42 -> 2225 | P42: =F42 -> Display | Q42: DMIE
E43: 2226 | F43: Pulser | O43: =E43 -> 2226 | P43: =F43 -> Pulser | Q43: DMIE
E44: 2227 | F44: Encoder | O44: =E44 -> 2227 | P44: =F44 -> Encoder | Q44: DMIE
...

Sheet CODE
B1: CODING | C1: BANKS | F1: SEGMENT
B2: BNC | C2: BDO NETWORK - CHECKING | F2: DHPP
B3: CBS | C3: CHINA BANK - SAVINGS | F3: DMIE
B4: EWC | C4: EASTWEST-CHECKING | F4: OPS
B5: FVC | C5: FIRST VALLEY -CHECKING
B6: KBS | C6: KATIPUNAN BANK-SAVINGS
B7: MBC | C7: METROBANK-CHECKING
B8: PNC | C8: PNB - CHECKING
B9: PSC | C9: PSBC - CHECKING
B10: PSS | C10: PSBC- SAVINGS
B11: RCS | C11: RCBC -SAVINGS
B12: COH | C12: CASH/CHECK ON HAND
B13: PNO | C13: PNB - OPEX
B14: ARC | C14: A/Receivables - CNR

Sheet COA
A3: COA | B3: ACCOUNT TITLES | C3: SEGMENT | D3: CLASSIFICATION | E3: CATEGORY | F3: Sub-Accounts | G3: Major Accounts
A4: 10000 | B4: Petty Cash Fund | C4: DHPP | D4: Cash & Cash in Bank | E4: Petty Cash | F4: Current Assets | G4: Asset
A5: 10010 | B5: Cash on Hand-DHPP | C5: DHPP | D5: Cash & Cash in Bank | E5: Cash on Hand | F5: Current Assets | G5: Asset
A6: 10013 | B6: Cash on Hand-DMIE | C6: DMIE | D6: Cash & Cash in Bank | E6: Cash on Hand | F6: Current Assets | G6: Asset
A7: 10016 | B7: Cash on Hand-OPS | C7: OPS | D7: Cash & Cash in Bank | E7: Cash on Hand | F7: Current Assets | G7: Asset
A8: 10020 | B8: Due from Other Bank_EW-DHPP | C8: DHPP | D8: Due From Other Bank | E8: Due from Banks | F8: Current Assets | G8: Asset
A9: 10023 | B9: Due from Other Bank_EW-DMIE | C9: DMIE | D9: Due From Other Bank | E9: Due from Banks | F9: Current Assets | G9: Asset
A10: 10026 | B10: Due from Other Bank_EW-OPS | C10: OPS | D10: Due From Other Bank | E10: Due from Banks | F10: Current Assets | G10: Asset
A11: 10030 | B11: Cash in Bank_1VB-DHPP | C11: DHPP | D11: Cash & Cash in Bank | E11: Cash in Bank | F11: Current Assets | G11: Asset
A12: 10033 | B12: Cash in Bank_1VB-DMIE | C12: DMIE | D12: Cash & Cash in Bank | E12: Cash in Bank | F12: Current Assets | G12: Asset
A13: 10036 | B13: Cash in Bank_1VB-OPS | C13: OPS | D13: Cash & Cash in Bank | E13: Cash in Bank | F13: Current Assets | G13: Asset
A14: 10040 | B14: Cash in Bank_PNB-DHPP | C14: DHPP | D14: Cash & Cash in Bank | E14: Cash in Bank | F14: Current Assets | G14: Asset
A15: 10043 | B15: Cash in Bank_PNB-DMIE | C15: DMIE | D15: Cash & Cash in Bank | E15: Cash in Bank | F15: Current Assets | G15: Asset
... A374: 66006 | B374: Other Gen. and Admin. Expenses_OPS | C374: OPS | D374: Non-Trade Expense | E374: Gen. and Admin. Expenses | F374: Non-Operating Expense | G374: Equity
