Workbook
Name ChartofAccounts: 'BEGINNING BALANCES'!$B$5:$B$108
Name ChartofAccounts: 'Chart of Accounts'!$B$6:$B$121
Name ChartofAccountsTable: 'BEGINNING BALANCES'!$B$5:$C$108
Name ChartofAccountsTable: 'Chart of Accounts'!$B$6:$C$121

Sheet BEGINNING BALANCES
B1: JULY 29-SEP.1,2025 | E1: =D2-E2 -> 0
B2: OPENING BALANCES | D2: =SUM(D5:D110) -> 0 | E2: =SUM(E5:E110) -> 0
B4: GL NO: | C4: Account Name | D4: Dr. | E4: Cr.
B5: 10000 | C5: ASSETS
B6: 10000 | C6: Current Assets
B7: 10010 | C7: Cash on Hand-DHPP
B8: 10040 | C8: Cash in Bank_PNB-DHPP
B9: 10030 | C9: Cash in Bank_1VB-DHPP
B10: 10080 | C10: Cash in Bank_MBTC-DHPP
B11: 10020 | C11: Cash in Bank_EW-DHPP
B12: 10060 | C12: Cash in Bank_KB-DHPP
B13: 10050 | C13: Cash in Bank_PSBC-DHPP
B14: 10110 | C14: Cash in Bank_PSBC CHECKING-DHPP
B15: 10070 | C15: Cash in Bank_BDO Unibank-DHPP
B17: 12000 | C17: RECEIVABLES
... B100: 6180 | C100: EXP - Depreciation Vehicles
B101: 6190 | C101: EXP - Gasoline Expenses | D101: 0 | E101: 0
B103: 7000 | C103: OTHER INCOME
B104: 7100 | C104: Finance Charge Income
B106: 8000 | C106: OTHER EXPENSES
B107: 8100 | C107: EXP - Interests
B108: 8200 | C108: EXP - Bank Charges

Sheet Chart of Accounts
B1: ='BEGINNING BALANCES'!B1 -> JULY 29-SEP.1,2025
B2: DISTRIBUTION AND HAULING OF PETROLEUM PRODUCTS | E2: =D3-E3 -> -281425 | I2: =SUM(I8:I123) -> 37930160 | J2: =SUM(J8:J123) -> 38056985 | K2: =SUM(K8:K123) -> 18474890 | L2: =SUM(L8:L123) -> 18629490 | M2: =SUM(M8:M123) -> 0 | N2: =SUM(N8:N123) -> 0 | O2: =SUM(O8:O123) -> 0 | P2: =SUM(P8:P123) -> 0
B3: TRIAL BALANCE | D3: =SUM(D6:D123) -> 56405050 | E3: =SUM(E6:E123) -> 56686475 | G3: ENDING BALANCES | I3: PAYMENT RECEIPTS | J3: PAYMENT RECEIPTS | K3: Upon Delivery | L3: Upon Delivery | M3: Fuel Delivery | N3: Fuel Delivery | O3: AR-Mems | P3: AR-Mems
B5: GL NO: | C5: Account Name | D5: Dr. | E5: Cr. | I5: Dr. | J5: Cr. | K5: Dr. | L5: Cr. | M5: Dr. | N5: Cr. | O5: Dr. | P5: Cr.
B6: 10000 | C6: ASSETS
B7: 1000 | C7: Current Assets
B8: 10010 | C8: Cash on Hand-DHPP | D8: =$I8+$K8+$M8+$O8 -> 249200 | E8: =$J8+$L8+$N8+$P8 -> 142275 | G8: ='BEGINNING BALANCES'!D7-'BEGINNING BALANCES'!E7+'Chart of Accounts'!D8-'Chart of Accounts'!E8 -> 106925 | I8: =SUMIF('PAYMENT RECEIPTS'!$H$9:$H$1048576,'Chart of Accounts'!B8,'PAYMENT RECEIPTS'!$J$9:$J$1048576) -> 249200 | J8: =SUMIF('PAYMENT RECEIPTS'!$H$9:$H$1048576,'Chart of Accounts'!B8,'PAYMENT RECEIPTS'!$K$9:$K$1048576) -> 142275 | K8: =SUMIF('UPON DELIVERY'!$K$131:$K$1048576,'Chart of Accounts'!B8,'UPON DELIVERY'!$M$131:$M$1048576) -> 0 | L8: =SUMIF('UPON DELIVERY'!$K$131:$K$1048576,'Chart of Accounts'!B8,'UPON DELIVERY'!$N$131:$N$1048576) -> 0 | M8: =SUMIF('FUEL INVENTORY'!$H$9:$H$1048576,'Chart of Accounts'!B8,'FUEL INVENTORY'!$J$9:$J$1048576) -> 0 | N8: =SUMIF('FUEL INVENTORY'!$H$9:$H$1048576,'Chart of Accounts'!B8,'FUEL INVENTORY'!$K$9:$K$1048576) -> 0 | O8: =SUMIF('AR-SUPPLIER'!$G$8:$G$1048576,'Chart of Accounts'!B8,'AR-SUPPLIER'!$I$8:$I$1048576) -> 0 | P8: =SUMIF('AR-SUPPLIER'!$G$8:$G$1048576,'Chart of Accounts'!B8,'AR-SUPPLIER'!$J$8:$J$1048576) -> 0
B9: 10040 | C9: Cash in Bank_PNB-DHPP | D9: =$I9+$K9+$M9+$O9 -> 9278550 | E9: =$J9+$L9+$N9+$P9 -> 0 | G9: ='BEGINNING BALANCES'!D8-'BEGINNING BALANCES'!E8+'Chart of Accounts'!D9-'Chart of Accounts'!E9 -> 9278550 | I9: =SUMIF('PAYMENT RECEIPTS'!$H$9:$H$1048576,'Chart of Accounts'!B9,'PAYMENT RECEIPTS'!$J$9:$J$1048576) -> 9278550 | J9: =SUMIF('PAYMENT RECEIPTS'!$H$9:$H$1048576,'Chart of Accounts'!B9,'PAYMENT RECEIPTS'!$K$9:$K$1048576) -> 0 | K9: =SUMIF('UPON DELIVERY'!$K$131:$K$1048576,'Chart of Accounts'!B9,'UPON DELIVERY'!$M$131:$M$1048576) -> 0 | L9: =SUMIF('UPON DELIVERY'!$K$131:$K$1048576,'Chart of Accounts'!B9,'UPON DELIVERY'!$N$131:$N$1048576) -> 0 | M9: =SUMIF('FUEL INVENTORY'!$H$9:$H$1048576,'Chart of Accounts'!B9,'FUEL INVENTORY'!$J$9:$J$1048576) -> 0 | N9: =SUMIF('FUEL INVENTORY'!$H$9:$H$1048576,'Chart of Accounts'!B9,'FUEL INVENTORY'!$K$9:$K$1048576) -> 0 | O9: =SUMIF('AR-SUPPLIER'!$G$8:$G$1048576,'Chart of Accounts'!B9,'AR-SUPPLIER'!$I$8:$I$1048576) -> 0 | P9: =SUMIF('AR-SUPPLIER'!$G$8:$G$1048576,'Chart of Accounts'!B9,'AR-SUPPLIER'!$J$8:$J$1048576) -> 0
B10: 10030 | C10: Cash in Bank_1VB-DHPP | D10: =$I10+$K10+$M10+$O10 -> 13816245 | E10: =$J10+$L10+$N10+$P10 -> 0 | G10: ='BEGINNING BALANCES'!D9-'BEGINNING BALANCES'!E9+'Chart of Accounts'!D10-'Chart of Accounts'!E10 -> 13816245 | I10: =SUMIF('PAYMENT RECEIPTS'!$H$9:$H$1048576,'Chart of Accounts'!B10,'PAYMENT RECEIPTS'!$J$9:$J$1048576) -> 13816245 | J10: =SUMIF('PAYMENT RECEIPTS'!$H$9:$H$1048576,'Chart of Accounts'!B10,'PAYMENT RECEIPTS'!$K$9:$K$1048576) -> 0 | K10: =SUMIF('UPON DELIVERY'!$K$131:$K$1048576,'Chart of Accounts'!B10,'UPON DELIVERY'!$M$131:$M$1048576) -> 0 | L10: =SUMIF('UPON DELIVERY'!$K$131:$K$1048576,'Chart of Accounts'!B10,'UPON DELIVERY'!$N$131:$N$1048576) -> 0 | M10: =SUMIF('FUEL INVENTORY'!$H$9:$H$1048576,'Chart of Accounts'!B10,'FUEL INVENTORY'!$J$9:$J$1048576) -> 0 | N10: =SUMIF('FUEL INVENTORY'!$H$9:$H$1048576,'Chart of Accounts'!B10,'FUEL INVENTORY'!$K$9:$K$1048576) -> 0 | O10: =SUMIF('AR-SUPPLIER'!$G$8:$G$1048576,'Chart of Accounts'!B10,'AR-SUPPLIER'!$I$8:$I$1048576) -> 0 | P10: =SUMIF('AR-SUPPLIER'!$G$8:$G$1048576,'Chart of Accounts'!B10,'AR-SUPPLIER'!$J$8:$J$1048576) -> 0
B11: 10080 | C11: Cash in Bank_MBTC-DHPP | D11: =$I11+$K11+$M11+$O11 -> 6573948 | E11: =$J11+$L11+$N11+$P11 -> 0 | G11: ='BEGINNING BALANCES'!D10-'BEGINNING BALANCES'!E10+'Chart of Accounts'!D11-'Chart of Accounts'!E11 -> 6573948 | I11: =SUMIF('PAYMENT RECEIPTS'!$H$9:$H$1048576,'Chart of Accounts'!B11,'PAYMENT RECEIPTS'!$J$9:$J$1048576) -> 6573948 | J11: =SUMIF('PAYMENT RECEIPTS'!$H$9:$H$1048576,'Chart of Accounts'!B11,'PAYMENT RECEIPTS'!$K$9:$K$1048576) -> 0 | K11: =SUMIF('UPON DELIVERY'!$K$131:$K$1048576,'Chart of Accounts'!B11,'UPON DELIVERY'!$M$131:$M$1048576) -> 0 | L11: =SUMIF('UPON DELIVERY'!$K$131:$K$1048576,'Chart of Accounts'!B11,'UPON DELIVERY'!$N$131:$N$1048576) -> 0 | M11: =SUMIF('FUEL INVENTORY'!$H$9:$H$1048576,'Chart of Accounts'!B11,'FUEL INVENTORY'!$J$9:$J$1048576) -> 0 | N11: =SUMIF('FUEL INVENTORY'!$H$9:$H$1048576,'Chart of Accounts'!B11,'FUEL INVENTORY'!$K$9:$K$1048576) -> 0 | O11: =SUMIF('AR-SUPPLIER'!$G$8:$G$1048576,'Chart of Accounts'!B11,'AR-SUPPLIER'!$I$8:$I$1048576) -> 0 | P11: =SUMIF('AR-SUPPLIER'!$G$8:$G$1048576,'Chart of Accounts'!B11,'AR-SUPPLIER'!$J$8:$J$1048576) -> 0
B12: 10020 | C12: Cash in Bank_EW-DHPP | D12: =$I12+$K12+$M12+$O12 -> 0 | E12: =$J12+$L12+$N12+$P12 -> 0 | G12: ='BEGINNING BALANCES'!D11-'BEGINNING BALANCES'!E11+'Chart of Accounts'!D12-'Chart of Accounts'!E12 -> 0 | I12: =SUMIF('PAYMENT RECEIPTS'!$H$9:$H$1048576,'Chart of Accounts'!B12,'PAYMENT RECEIPTS'!$J$9:$J$1048576) -> 0 | J12: =SUMIF('PAYMENT RECEIPTS'!$H$9:$H$1048576,'Chart of Accounts'!B12,'PAYMENT RECEIPTS'!$K$9:$K$1048576) -> 0 | K12: =SUMIF('UPON DELIVERY'!$K$131:$K$1048576,'Chart of Accounts'!B12,'UPON DELIVERY'!$M$131:$M$1048576) -> 0 | L12: =SUMIF('UPON DELIVERY'!$K$131:$K$1048576,'Chart of Accounts'!B12,'UPON DELIVERY'!$N$131:$N$1048576) -> 0 | M12: =SUMIF('FUEL INVENTORY'!$H$9:$H$1048576,'Chart of Accounts'!B12,'FUEL INVENTORY'!$J$9:$J$1048576) -> 0 | N12: =SUMIF('FUEL INVENTORY'!$H$9:$H$1048576,'Chart of Accounts'!B12,'FUEL INVENTORY'!$K$9:$K$1048576) -> 0 | O12: =SUMIF('AR-SUPPLIER'!$G$8:$G$1048576,'Chart of Accounts'!B12,'AR-SUPPLIER'!$I$8:$I$1048576) -> 0 | P12: =SUMIF('AR-SUPPLIER'!$G$8:$G$1048576,'Chart of Accounts'!B12,'AR-SUPPLIER'!$J$8:$J$1048576) -> 0
B13: 10060 | C13: Cash in Bank_KB-DHPP | D13: =$I13+$K13+$M13+$O13 -> 895450 | E13: =$J13+$L13+$N13+$P13 -> 0 | G13: ='BEGINNING BALANCES'!D12-'BEGINNING BALANCES'!E12+'Chart of Accounts'!D13-'Chart of Accounts'!E13 -> 895450 | I13: =SUMIF('PAYMENT RECEIPTS'!$H$9:$H$1048576,'Chart of Accounts'!B13,'PAYMENT RECEIPTS'!$J$9:$J$1048576) -> 895450 | J13: =SUMIF('PAYMENT RECEIPTS'!$H$9:$H$1048576,'Chart of Accounts'!B13,'PAYMENT RECEIPTS'!$K$9:$K$1048576) -> 0 | K13: =SUMIF('UPON DELIVERY'!$K$131:$K$1048576,'Chart of Accounts'!B13,'UPON DELIVERY'!$M$131:$M$1048576) -> 0 | L13: =SUMIF('UPON DELIVERY'!$K$131:$K$1048576,'Chart of Accounts'!B13,'UPON DELIVERY'!$N$131:$N$1048576) -> 0 | M13: =SUMIF('FUEL INVENTORY'!$H$9:$H$1048576,'Chart of Accounts'!B13,'FUEL INVENTORY'!$J$9:$J$1048576) -> 0 | N13: =SUMIF('FUEL INVENTORY'!$H$9:$H$1048576,'Chart of Accounts'!B13,'FUEL INVENTORY'!$K$9:$K$1048576) -> 0 | O13: =SUMIF('AR-SUPPLIER'!$G$8:$G$1048576,'Chart of Accounts'!B13,'AR-SUPPLIER'!$I$8:$I$1048576) -> 0 | P13: =SUMIF('AR-SUPPLIER'!$G$8:$G$1048576,'Chart of Accounts'!B13,'AR-SUPPLIER'!$J$8:$J$1048576) -> 0
B14: 10050 | C14: Cash in Bank_PSBC-DHPP | D14: =$I14+$K14+$M14+$O14 -> 0 | E14: =$J14+$L14+$N14+$P14 -> 0 | G14: ='BEGINNING BALANCES'!D13-'BEGINNING BALANCES'!E13+'Chart of Accounts'!D14-'Chart of Accounts'!E14 -> 0 | I14: =SUMIF('PAYMENT RECEIPTS'!$H$9:$H$1048576,'Chart of Accounts'!B14,'PAYMENT RECEIPTS'!$J$9:$J$1048576) -> 0 | J14: =SUMIF('PAYMENT RECEIPTS'!$H$9:$H$1048576,'Chart of Accounts'!B14,'PAYMENT RECEIPTS'!$K$9:$K$1048576) -> 0 | K14: =SUMIF('UPON DELIVERY'!$K$131:$K$1048576,'Chart of Accounts'!B14,'UPON DELIVERY'!$M$131:$M$1048576) -> 0 | L14: =SUMIF('UPON DELIVERY'!$K$131:$K$1048576,'Chart of Accounts'!B14,'UPON DELIVERY'!$N$131:$N$1048576) -> 0 | M14: =SUMIF('FUEL INVENTORY'!$H$9:$H$1048576,'Chart of Accounts'!B14,'FUEL INVENTORY'!$J$9:$J$1048576) -> 0 | N14: =SUMIF('FUEL INVENTORY'!$H$9:$H$1048576,'Chart of Accounts'!B14,'FUEL INVENTORY'!$K$9:$K$1048576) -> 0 | O14: =SUMIF('AR-SUPPLIER'!$G$8:$G$1048576,'Chart of Accounts'!B14,'AR-SUPPLIER'!$I$8:$I$1048576) -> 0 | P14: =SUMIF('AR-SUPPLIER'!$G$8:$G$1048576,'Chart of Accounts'!B14,'AR-SUPPLIER'!$J$8:$J$1048576) -> 0
B15: 10110 | C15: Cash in Bank_PSBC CHECKING-DHPP | D15: =$I15+$K15+$M15+$O15 -> 2738575 | E15: =$J15+$L15+$N15+$P15 -> 0 | G15: ='BEGINNING BALANCES'!D14-'BEGINNING BALANCES'!E14+'Chart of Accounts'!D15-'Chart of Accounts'!E15 -> 2738575 | I15: =SUMIF('PAYMENT RECEIPTS'!$H$9:$H$1048576,'Chart of Accounts'!B15,'PAYMENT RECEIPTS'!$J$9:$J$1048576) -> 2738575 | J15: =SUMIF('PAYMENT RECEIPTS'!$H$9:$H$1048576,'Chart of Accounts'!B15,'PAYMENT RECEIPTS'!$K$9:$K$1048576) -> 0 | K15: =SUMIF('UPON DELIVERY'!$K$131:$K$1048576,'Chart of Accounts'!B15,'UPON DELIVERY'!$M$131:$M$1048576) -> 0 | L15: =SUMIF('UPON DELIVERY'!$K$131:$K$1048576,'Chart of Accounts'!B15,'UPON DELIVERY'!$N$131:$N$1048576) -> 0 | M15: =SUMIF('FUEL INVENTORY'!$H$9:$H$1048576,'Chart of Accounts'!B15,'FUEL INVENTORY'!$J$9:$J$1048576) -> 0 | N15: =SUMIF('FUEL INVENTORY'!$H$9:$H$1048576,'Chart of Accounts'!B15,'FUEL INVENTORY'!$K$9:$K$1048576) -> 0 | O15: =SUMIF('AR-SUPPLIER'!$G$8:$G$1048576,'Chart of Accounts'!B15,'AR-SUPPLIER'!$I$8:$I$1048576) -> 0 | P15: =SUMIF('AR-SUPPLIER'!$G$8:$G$1048576,'Chart of Accounts'!B15,'AR-SUPPLIER'!$J$8:$J$1048576) -> 0
B16: 10070 | C16: Cash in Bank_BDO Unibank-DHPP | D16: =$I16+$K16+$M16+$O16 -> 2136840 | E16: =$J16+$L16+$N16+$P16 -> 0 | G16: ='BEGINNING BALANCES'!D15-'BEGINNING BALANCES'!E15+'Chart of Accounts'!D16-'Chart of Accounts'!E16 -> 2136840 | I16: =SUMIF('PAYMENT RECEIPTS'!$H$9:$H$1048576,'Chart of Accounts'!B16,'PAYMENT RECEIPTS'!$J$9:$J$1048576) -> 2136840 | J16: =SUMIF('PAYMENT RECEIPTS'!$H$9:$H$1048576,'Chart of Accounts'!B16,'PAYMENT RECEIPTS'!$K$9:$K$1048576) -> 0 | K16: =SUMIF('UPON DELIVERY'!$K$131:$K$1048576,'Chart of Accounts'!B16,'UPON DELIVERY'!$M$131:$M$1048576) -> 0 | L16: =SUMIF('UPON DELIVERY'!$K$131:$K$1048576,'Chart of Accounts'!B16,'UPON DELIVERY'!$N$131:$N$1048576) -> 0 | M16: =SUMIF('FUEL INVENTORY'!$H$9:$H$1048576,'Chart of Accounts'!B16,'FUEL INVENTORY'!$J$9:$J$1048576) -> 0 | N16: =SUMIF('FUEL INVENTORY'!$H$9:$H$1048576,'Chart of Accounts'!B16,'FUEL INVENTORY'!$K$9:$K$1048576) -> 0 | O16: =SUMIF('AR-SUPPLIER'!$G$8:$G$1048576,'Chart of Accounts'!B16,'AR-SUPPLIER'!$I$8:$I$1048576) -> 0 | P16: =SUMIF('AR-SUPPLIER'!$G$8:$G$1048576,'Chart of Accounts'!B16,'AR-SUPPLIER'!$J$8:$J$1048576) -> 0
G17: ='BEGINNING BALANCES'!D16-'BEGINNING BALANCES'!E16+'Chart of Accounts'!D17-'Chart of Accounts'!E17 -> 0 | I17: =SUMIF('PAYMENT RECEIPTS'!$H$9:$H$1048576,'Chart of Accounts'!B17,'PAYMENT RECEIPTS'!$J$9:$J$1048576) -> 0 | J17: =SUMIF('PAYMENT RECEIPTS'!$H$9:$H$1048576,'Chart of Accounts'!B17,'PAYMENT RECEIPTS'!$K$9:$K$1048576) -> 0 | K17: =SUMIF('UPON DELIVERY'!$K$131:$K$1048576,'Chart of Accounts'!B17,'UPON DELIVERY'!$M$131:$M$1048576) -> 0 | L17: =SUMIF('UPON DELIVERY'!$K$131:$K$1048576,'Chart of Accounts'!B17,'UPON DELIVERY'!$N$131:$N$1048576) -> 0 | M17: =SUMIF('FUEL INVENTORY'!$H$9:$H$1048576,'Chart of Accounts'!B17,'FUEL INVENTORY'!$J$9:$J$1048576) -> 0 | N17: =SUMIF('FUEL INVENTORY'!$H$9:$H$1048576,'Chart of Accounts'!B17,'FUEL INVENTORY'!$K$9:$K$1048576) -> 0 | O17: =SUMIF('AR-SUPPLIER'!$G$8:$G$1048576,'Chart of Accounts'!B17,'AR-SUPPLIER'!$I$8:$I$1048576) -> 0 | P17: =SUMIF('AR-SUPPLIER'!$G$8:$G$1048576,'Chart of Accounts'!B17,'AR-SUPPLIER'!$J$8:$J$1048576) -> 0
B18: 1200 | C18: RECEIVABLES
B19: 12030 | C19: A/Receivables - Fuel Clients
B20: 12040 | C20: Advances to Suppliers - DHPP
B22: 1200 | C22: RECEIVABLES | D22: =I22+K22+M22+O22 -> 0 | E22: =$J22+$L22+$N22+$P22 -> 0 | G22: ='BEGINNING BALANCES'!D24-'BEGINNING BALANCES'!E24+'Chart of Accounts'!D22-'Chart of Accounts'!E22 -> 0 | I22: =SUMIF('PAYMENT RECEIPTS'!$H$9:$H$1048576,'Chart of Accounts'!B22,'PAYMENT RECEIPTS'!$J$9:$J$1048576) -> 0 | J22: =SUMIF('PAYMENT RECEIPTS'!$H$9:$H$1048576,'Chart of Accounts'!B22,'PAYMENT RECEIPTS'!$K$9:$K$1048576) -> 0 | K22: =SUMIF('UPON DELIVERY'!$K$131:$K$1048576,'Chart of Accounts'!B22,'UPON DELIVERY'!$M$131:$M$1048576) -> 0 | L22: =SUMIF('UPON DELIVERY'!$K$131:$K$1048576,'Chart of Accounts'!B22,'UPON DELIVERY'!$N$131:$N$1048576) -> 0 | M22: =SUMIF('FUEL INVENTORY'!$H$9:$H$1048576,'Chart of Accounts'!B22,'FUEL INVENTORY'!$J$9:$J$1048576) -> 0 | N22: =SUMIF('FUEL INVENTORY'!$H$9:$H$1048576,'Chart of Accounts'!B22,'FUEL INVENTORY'!$K$9:$K$1048576) -> 0 | O22: =SUMIF('AR-SUPPLIER'!$G$8:$G$1048576,'Chart of Accounts'!B22,'AR-SUPPLIER'!$I$8:$I$1048576) -> 0 | P22: =SUMIF('AR-SUPPLIER'!$G$8:$G$1048576,'Chart of Accounts'!B22,'AR-SUPPLIER'!$J$8:$J$1048576) -> 0
B23: 12020 | C23: A/Receivables - Other Current -DHPP
B24: 12030 | C24: A/Receivables - Fuel Clients | D24: =$I24+$K24+$M24+$O24 -> 2351412 | E24: =$J24+$L24+$N24+$P24 -> 2642050 | G24: ='BEGINNING BALANCES'!D25-'BEGINNING BALANCES'!E25+'Chart of Accounts'!D24-'Chart of Accounts'!E24 -> -290638 | I24: =SUMIF('PAYMENT RECEIPTS'!$H$9:$H$1048576,'Chart of Accounts'!B24,'PAYMENT RECEIPTS'!$J$9:$J$1048576) -> 0 | J24: =SUMIF('PAYMENT RECEIPTS'!$H$9:$H$1048576,'Chart of Accounts'!B24,'PAYMENT RECEIPTS'!$K$9:$K$1048576) -> 2642050 | K24: =SUMIF('UPON DELIVERY'!$K$131:$K$1048576,'Chart of Accounts'!B24,'UPON DELIVERY'!$M$131:$M$1048576) -> 2351412 | L24: =SUMIF('UPON DELIVERY'!$K$131:$K$1048576,'Chart of Accounts'!B24,'UPON DELIVERY'!$N$131:$N$1048576) -> 0 | M24: =SUMIF('FUEL INVENTORY'!$H$9:$H$1048576,'Chart of Accounts'!B24,'FUEL INVENTORY'!$J$9:$J$1048576) -> 0 | N24: =SUMIF('FUEL INVENTORY'!$H$9:$H$1048576,'Chart of Accounts'!B24,'FUEL INVENTORY'!$K$9:$K$1048576) -> 0 | O24: =SUMIF('AR-SUPPLIER'!$G$8:$G$1048576,'Chart of Accounts'!B24,'AR-SUPPLIER'!$I$8:$I$1048576) -> 0 | P24: =SUMIF('AR-SUPPLIER'!$G$8:$G$1048576,'Chart of Accounts'!B24,'AR-SUPPLIER'!$J$8:$J$1048576) -> 0
B25: 12040 | C25: Advances to Suppliers - DHPP | D25: =$I25+$K25+$M25+$O25 -> 0 | E25: =$J25+$L25+$N25+$P25 -> 0 | G25: ='BEGINNING BALANCES'!D26-'BEGINNING BALANCES'!E26+'Chart of Accounts'!D25-'Chart of Accounts'!E25 -> 0 | I25: =SUMIF('PAYMENT RECEIPTS'!$H$9:$H$1048576,'Chart of Accounts'!B25,'PAYMENT RECEIPTS'!$J$9:$J$1048576) -> 0 | J25: =SUMIF('PAYMENT RECEIPTS'!$H$9:$H$1048576,'Chart of Accounts'!B25,'PAYMENT RECEIPTS'!$K$9:$K$1048576) -> 0 | K25: =SUMIF('UPON DELIVERY'!$K$131:$K$1048576,'Chart of Accounts'!B25,'UPON DELIVERY'!$M$131:$M$1048576) -> 0 | L25: =SUMIF('UPON DELIVERY'!$K$131:$K$1048576,'Chart of Accounts'!B25,'UPON DELIVERY'!$N$131:$N$1048576) -> 0 | M25: =SUMIF('FUEL INVENTORY'!$H$9:$H$1048576,'Chart of Accounts'!B25,'FUEL INVENTORY'!$J$9:$J$1048576) -> 0 | N25: =SUMIF('FUEL INVENTORY'!$H$9:$H$1048576,'Chart of Accounts'!B25,'FUEL INVENTORY'!$K$9:$K$1048576) -> 0 | O25: =SUMIF('AR-SUPPLIER'!$G$8:$G$1048576,'Chart of Accounts'!B25,'AR-SUPPLIER'!$I$8:$I$1048576) -> 0 | P25: =SUMIF('AR-SUPPLIER'!$G$8:$G$1048576,'Chart of Accounts'!B25,'AR-SUPPLIER'!$J$8:$J$1048576) -> 0
B26: 15500 | C26: Due from Other Cos. - DHPP | D26: =$I26+$K26+$M26+$O26 -> 2241352 | E26: =$J26+$L26+$N26+$P26 -> 0 | G26: ='BEGINNING BALANCES'!D27-'BEGINNING BALANCES'!E27+'Chart of Accounts'!D26-'Chart of Accounts'!E26 -> 2241352 | I26: =SUMIF('PAYMENT RECEIPTS'!$H$9:$H$1048576,'Chart of Accounts'!B26,'PAYMENT RECEIPTS'!$J$9:$J$1048576) -> 2241352 | J26: =SUMIF('PAYMENT RECEIPTS'!$H$9:$H$1048576,'Chart of Accounts'!B26,'PAYMENT RECEIPTS'!$K$9:$K$1048576) -> 0 | K26: =SUMIF('UPON DELIVERY'!$K$131:$K$1048576,'Chart of Accounts'!B26,'UPON DELIVERY'!$M$131:$M$1048576) -> 0 | L26: =SUMIF('UPON DELIVERY'!$K$131:$K$1048576,'Chart of Accounts'!B26,'UPON DELIVERY'!$N$131:$N$1048576) -> 0 | M26: =SUMIF('FUEL INVENTORY'!$H$9:$H$1048576,'Chart of Accounts'!B26,'FUEL INVENTORY'!$J$9:$J$1048576) -> 0 | N26: =SUMIF('FUEL INVENTORY'!$H$9:$H$1048576,'Chart of Accounts'!B26,'FUEL INVENTORY'!$K$9:$K$1048576) -> 0 | O26: =SUMIF('AR-SUPPLIER'!$G$8:$G$1048576,'Chart of Accounts'!B26,'AR-SUPPLIER'!$I$8:$I$1048576) -> 0 | P26: =SUMIF('AR-SUPPLIER'!$G$8:$G$1048576,'Chart of Accounts'!B26,'AR-SUPPLIER'!$J$8:$J$1048576) -> 0
B27: 1300 | C27: INVENTORIES | D27: =$I27+$K27+$M27+$O27 -> 0 | E27: =$J27+$L27+$N27+$P27 -> 0 | I27: =SUMIF('PAYMENT RECEIPTS'!$H$9:$H$1048576,'Chart of Accounts'!B27,'PAYMENT RECEIPTS'!$J$9:$J$1048576) -> 0 | J27: =SUMIF('PAYMENT RECEIPTS'!$H$9:$H$1048576,'Chart of Accounts'!B27,'PAYMENT RECEIPTS'!$K$9:$K$1048576) -> 0 | K27: =SUMIF('UPON DELIVERY'!$K$131:$K$1048576,'Chart of Accounts'!B27,'UPON DELIVERY'!$M$131:$M$1048576) -> 0 | L27: =SUMIF('UPON DELIVERY'!$K$131:$K$1048576,'Chart of Accounts'!B27,'UPON DELIVERY'!$N$131:$N$1048576) -> 0 | M27: =SUMIF('FUEL INVENTORY'!$H$9:$H$1048576,'Chart of Accounts'!B27,'FUEL INVENTORY'!$J$9:$J$1048576) -> 0 | N27: =SUMIF('FUEL INVENTORY'!$H$9:$H$1048576,'Chart of Accounts'!B27,'FUEL INVENTORY'!$K$9:$K$1048576) -> 0 | O27: =SUMIF('AR-SUPPLIER'!$G$8:$G$1048576,'Chart of Accounts'!B27,'AR-SUPPLIER'!$I$8:$I$1048576) -> 0 | P27: =SUMIF('AR-SUPPLIER'!$G$8:$G$1048576,'Chart of Accounts'!B27,'AR-SUPPLIER'!$J$8:$J$1048576) -> 0
B28: 13000 | C28: Fuel Inventory | D28: =$I28+$K28+$M28+$O28 -> 0 | E28: =$J28+$L28+$N28+$P28 -> 0 | G28: ='BEGINNING BALANCES'!D29-'BEGINNING BALANCES'!E29+'Chart of Accounts'!D28-'Chart of Accounts'!E28 -> 0 | I28: =SUMIF('PAYMENT RECEIPTS'!$H$9:$H$1048576,'Chart of Accounts'!B28,'PAYMENT RECEIPTS'!$J$9:$J$1048576) -> 0 | J28: =SUMIF('PAYMENT RECEIPTS'!$H$9:$H$1048576,'Chart of Accounts'!B28,'PAYMENT RECEIPTS'!$K$9:$K$1048576) -> 0 | K28: =SUMIF('UPON DELIVERY'!$K$131:$K$1048576,'Chart of Accounts'!B28,'UPON DELIVERY'!$M$131:$M$1048576) -> 0 | L28: =SUMIF('UPON DELIVERY'!$K$131:$K$1048576,'Chart of Accounts'!B28,'UPON DELIVERY'!$N$131:$N$1048576) -> 0 | M28: =SUMIF('FUEL INVENTORY'!$H$9:$H$1048576,'Chart of Accounts'!B28,'FUEL INVENTORY'!$J$9:$J$1048576) -> 0 | N28: =SUMIF('FUEL INVENTORY'!$H$9:$H$1048576,'Chart of Accounts'!B28,'FUEL INVENTORY'!$K$9:$K$1048576) -> 0 | O28: =SUMIF('AR-SUPPLIER'!$G$8:$G$1048576,'Chart of Accounts'!B28,'AR-SUPPLIER'!$I$8:$I$1048576) -> 0 | P28: =SUMIF('AR-SUPPLIER'!$G$8:$G$1048576,'Chart of Accounts'!B28,'AR-SUPPLIER'!$J$8:$J$1048576) -> 0
B29: 13010 | C29: Fuel Inventory at Dohinob | D29: =$I29+$K29+$M29+$O29 -> 0 | E29: =$J29+$L29+$N29+$P29 -> 0 | G29: ='BEGINNING BALANCES'!D30-'BEGINNING BALANCES'!E30+'Chart of Accounts'!D29-'Chart of Accounts'!E29 -> 0 | I29: =SUMIF('PAYMENT RECEIPTS'!$H$9:$H$1048576,'Chart of Accounts'!B29,'PAYMENT RECEIPTS'!$J$9:$J$1048576) -> 0 | J29: =SUMIF('PAYMENT RECEIPTS'!$H$9:$H$1048576,'Chart of Accounts'!B29,'PAYMENT RECEIPTS'!$K$9:$K$1048576) -> 0 | K29: =SUMIF('UPON DELIVERY'!$K$131:$K$1048576,'Chart of Accounts'!B29,'UPON DELIVERY'!$M$131:$M$1048576) -> 0 | L29: =SUMIF('UPON DELIVERY'!$K$131:$K$1048576,'Chart of Accounts'!B29,'UPON DELIVERY'!$N$131:$N$1048576) -> 0 | M29: =SUMIF('FUEL INVENTORY'!$H$9:$H$1048576,'Chart of Accounts'!B29,'FUEL INVENTORY'!$J$9:$J$1048576) -> 0 | N29: =SUMIF('FUEL INVENTORY'!$H$9:$H$1048576,'Chart of Accounts'!B29,'FUEL INVENTORY'!$K$9:$K$1048576) -> 0 | O29: =SUMIF('AR-SUPPLIER'!$G$8:$G$1048576,'Chart of Accounts'!B29,'AR-SUPPLIER'!$I$8:$I$1048576) -> 0 | P29: =SUMIF('AR-SUPPLIER'!$G$8:$G$1048576,'Chart of Accounts'!B29,'AR-SUPPLIER'!$J$8:$J$1048576) -> 0
B30: 13020 | C30: Fuel Inventory at Office | G30: ='BEGINNING BALANCES'!D31-'BEGINNING BALANCES'!E31+'Chart of Accounts'!D30-'Chart of Accounts'!E30 -> 0 | I30: =SUMIF('PAYMENT RECEIPTS'!$H$9:$H$1048576,'Chart of Accounts'!B30,'PAYMENT RECEIPTS'!$J$9:$J$1048576) -> 0 | J30: =SUMIF('PAYMENT RECEIPTS'!$H$9:$H$1048576,'Chart of Accounts'!B30,'PAYMENT RECEIPTS'!$K$9:$K$1048576) -> 0 | K30: =SUMIF('UPON DELIVERY'!$K$131:$K$1048576,'Chart of Accounts'!B30,'UPON DELIVERY'!$M$131:$M$1048576) -> 0 | L30: =SUMIF('UPON DELIVERY'!$K$131:$K$1048576,'Chart of Accounts'!B30,'UPON DELIVERY'!$N$131:$N$1048576) -> 0 | M30: =SUMIF('FUEL INVENTORY'!$H$9:$H$1048576,'Chart of Accounts'!B30,'FUEL INVENTORY'!$J$9:$J$1048576) -> 0 | N30: =SUMIF('FUEL INVENTORY'!$H$9:$H$1048576,'Chart of Accounts'!B30,'FUEL INVENTORY'!$K$9:$K$1048576) -> 0 | O30: =SUMIF('AR-SUPPLIER'!$G$8:$G$1048576,'Chart of Accounts'!B30,'AR-SUPPLIER'!$I$8:$I$1048576) -> 0 | P30: =SUMIF('AR-SUPPLIER'!$G$8:$G$1048576,'Chart of Accounts'!B30,'AR-SUPPLIER'!$J$8:$J$1048576) -> 0
B32: 1400 | C32: PREPAID EXPENSES and OTHER CURRENT ASSETS
B33: 1410 | C33: PREPAID - Insurance
B50: 2000 | C50: LIABILITIES
B52: 2100 | C52: PAYABLES | I52: =SUMIF('PAYMENT RECEIPTS'!$H$9:$H$1048576,'Chart of Accounts'!B52,'PAYMENT RECEIPTS'!$J$9:$J$1048576) -> 0 | J52: =SUMIF('PAYMENT RECEIPTS'!$H$9:$H$1048576,'Chart of Accounts'!B52,'PAYMENT RECEIPTS'!$K$9:$K$1048576) -> 0 | K52: =SUMIF('UPON DELIVERY'!$K$131:$K$1048576,'Chart of Accounts'!B52,'UPON DELIVERY'!$M$131:$M$1048576) -> 0 | L52: =SUMIF('UPON DELIVERY'!$K$131:$K$1048576,'Chart of Accounts'!B52,'UPON DELIVERY'!$N$131:$N$1048576) -> 0 | M52: =SUMIF('FUEL INVENTORY'!$H$9:$H$1048576,'Chart of Accounts'!B52,'FUEL INVENTORY'!$J$9:$J$1048576) -> 0 | N52: =SUMIF('FUEL INVENTORY'!$H$9:$H$1048576,'Chart of Accounts'!B52,'FUEL INVENTORY'!$K$9:$K$1048576) -> 0 | O52: =SUMIF('AR-SUPPLIER'!$G$8:$G$1048576,'Chart of Accounts'!B52,'AR-SUPPLIER'!$I$8:$I$1048576) -> 0 | P52: =SUMIF('AR-SUPPLIER'!$G$8:$G$1048576,'Chart of Accounts'!B52,'AR-SUPPLIER'!$J$8:$J$1048576) -> 0
B53: 21000 | C53: Unearned Revenue - DHPP
B54: 20000 | C54: A/Payables - Current - DHPP
B55: 2130 | C55: VAT - Input
B56: 21000 | C56: Unearned Revenue - DHPP | D56: =$I56+$K56+$M56+$O56 -> 16123478 | E56: =$J56+$L56+$N56+$P56 -> 35272660 | G56: ='BEGINNING BALANCES'!D57-'BEGINNING BALANCES'!E57+'Chart of Accounts'!D56-'Chart of Accounts'!E56 -> -19149182 | I56: =SUMIF('PAYMENT RECEIPTS'!$H$9:$H$1048576,'Chart of Accounts'!B56,'PAYMENT RECEIPTS'!$J$9:$J$1048576) -> 0 | J56: =SUMIF('PAYMENT RECEIPTS'!$H$9:$H$1048576,'Chart of Accounts'!B56,'PAYMENT RECEIPTS'!$K$9:$K$1048576) -> 35272660 | K56: =SUMIF('UPON DELIVERY'!$K$131:$K$1048576,'Chart of Accounts'!B56,'UPON DELIVERY'!$M$131:$M$1048576) -> 16123478 | L56: =SUMIF('UPON DELIVERY'!$K$131:$K$1048576,'Chart of Accounts'!B56,'UPON DELIVERY'!$N$131:$N$1048576) -> 0 | M56: =SUMIF('FUEL INVENTORY'!$H$9:$H$1048576,'Chart of Accounts'!B56,'FUEL INVENTORY'!$J$9:$J$1048576) -> 0 | N56: =SUMIF('FUEL INVENTORY'!$H$9:$H$1048576,'Chart of Accounts'!B56,'FUEL INVENTORY'!$K$9:$K$1048576) -> 0 | O56: =SUMIF('AR-SUPPLIER'!$G$8:$G$1048576,'Chart of Accounts'!B56,'AR-SUPPLIER'!$I$8:$I$1048576) -> 0 | P56: =SUMIF('AR-SUPPLIER'!$G$8:$G$1048576,'Chart of Accounts'!B56,'AR-SUPPLIER'!$J$8:$J$1048576) -> 0
B57: 20000 | C57: A/Payables - Current - DHPP | D57: =$I57+$K57+$M57+$O57 -> 0 | E57: =$J57+$L57+$N57+$P57 -> 0 | G57: ='BEGINNING BALANCES'!D58-'BEGINNING BALANCES'!E58+'Chart of Accounts'!D57-'Chart of Accounts'!E57 -> 0 | I57: =SUMIF('PAYMENT RECEIPTS'!$H$9:$H$1048576,'Chart of Accounts'!B57,'PAYMENT RECEIPTS'!$J$9:$J$1048576) -> 0 | J57: =SUMIF('PAYMENT RECEIPTS'!$H$9:$H$1048576,'Chart of Accounts'!B57,'PAYMENT RECEIPTS'!$K$9:$K$1048576) -> 0 | K57: =SUMIF('UPON DELIVERY'!$K$131:$K$1048576,'Chart of Accounts'!B57,'UPON DELIVERY'!$M$131:$M$1048576) -> 0 | L57: =SUMIF('UPON DELIVERY'!$K$131:$K$1048576,'Chart of Accounts'!B57,'UPON DELIVERY'!$N$131:$N$1048576) -> 0 | M57: =SUMIF('FUEL INVENTORY'!$H$9:$H$1048576,'Chart of Accounts'!B57,'FUEL INVENTORY'!$J$9:$J$1048576) -> 0 | N57: =SUMIF('FUEL INVENTORY'!$H$9:$H$1048576,'Chart of Accounts'!B57,'FUEL INVENTORY'!$K$9:$K$1048576) -> 0 | O57: =SUMIF('AR-SUPPLIER'!$G$8:$G$1048576,'Chart of Accounts'!B57,'AR-SUPPLIER'!$I$8:$I$1048576) -> 0 | P57: =SUMIF('AR-SUPPLIER'!$G$8:$G$1048576,'Chart of Accounts'!B57,'AR-SUPPLIER'!$J$8:$J$1048576) -> 0
D58: =$I58+$K58+$M58+$O58 -> 0 | E58: =$J58+$L58+$N58+$P58 -> 0
B59: 4000 | C59: REVENUE
B60: 40000 | C60: Sales -Fuel Hauling | D60: =$I60+$K60+$M60+$O60 -> 0 | E60: =$J60+$L60+$N60+$P60 -> 18629490 | G60: ='BEGINNING BALANCES'!D61-'BEGINNING BALANCES'!E61+'Chart of Accounts'!D60-'Chart of Accounts'!E60 -> -18629490 | I60: =SUMIF('PAYMENT RECEIPTS'!$H$9:$H$1048576,'Chart of Accounts'!B60,'PAYMENT RECEIPTS'!$J$9:$J$1048576) -> 0 | J60: =SUMIF('PAYMENT RECEIPTS'!$H$9:$H$1048576,'Chart of Accounts'!B60,'PAYMENT RECEIPTS'!$K$9:$K$1048576) -> 0 | K60: =SUMIF('UPON DELIVERY'!$K$131:$K$1048576,'Chart of Accounts'!B60,'UPON DELIVERY'!$M$131:$M$1048576) -> 0 | L60: =SUMIF('UPON DELIVERY'!$K$131:$K$1048576,'Chart of Accounts'!B60,'UPON DELIVERY'!$N$131:$N$1048576) -> 18629490 | M60: =SUMIF('FUEL INVENTORY'!$H$9:$H$1048576,'Chart of Accounts'!B60,'FUEL INVENTORY'!$J$9:$J$1048576) -> 0 | N60: =SUMIF('FUEL INVENTORY'!$H$9:$H$1048576,'Chart of Accounts'!B60,'FUEL INVENTORY'!$K$9:$K$1048576) -> 0 | O60: =SUMIF('AR-SUPPLIER'!$G$8:$G$1048576,'Chart of Accounts'!B60,'AR-SUPPLIER'!$I$8:$I$1048576) -> 0 | P60: =SUMIF('AR-SUPPLIER'!$G$8:$G$1048576,'Chart of Accounts'!B60,'AR-SUPPLIER'!$J$8:$J$1048576) -> 0
...

Sheet PAYMENT RECEIPTS
A1: AUGUST 1-31,2025 | B1: SEP. 8-OCT.6,2025
B2: ='Chart of Accounts'!B2 -> DISTRIBUTION AND HAULING OF PETROLEUM PRODUCTS
B3: GENERAL JOURNAL FOR FUEL ORDERS WITH PAYMENTS (STMIET)
B5: Data last entry date | K5: =J6-K6 -> 0
J6: =SUBTOTAL(9,J9:J19768) -> 38056985 | K6: =SUBTOTAL(9,K9:K19768) -> 38056985
B7: Date | C7: CYCLE | D7: Supplier/Customer Code | E7: ACKNOWLEDGMENT RECEIPT # | F7: PO # | G7: Description | H7: CoA | I7: Account Name | J7: Debit | K7: Credit
J8: =IF(SUM(J9:J39)=SUM(K9:K39),"Balance","Not Balance") -> Not Balance
C9: NOV. 1- 3, 2025 | E9: REFER TO COLLECTION SUMMARY | G9: TOTAL COLLECTIONS FOR THE WEEK-PNB CHECKING | H9: 10040 | I9: =IF(H9<>"",VLOOKUP(H9,ChartofAccountsTable,2,FALSE),"") -> Cash in Bank_PNB-DHPP | J9: 541975
C10: NOV. 1- 3, 2025 | E10: REFER TO COLLECTION SUMMARY | G10: TOTAL COLLECTIONS FOR THE WEEK-MBTC CHECKING | H10: 10080 | I10: =IF(H10<>"",VLOOKUP(H10,ChartofAccountsTable,2,FALSE),"") -> Cash in Bank_MBTC-DHPP | J10: 406973
C11: NOV. 1- 3, 2025 | E11: REFER TO COLLECTION SUMMARY | G11: TOTAL COLLECTIONS FOR THE WEEK-BDO CHECKING | H11: 10070 | I11: =IF(H11<>"",VLOOKUP(H11,ChartofAccountsTable,2,FALSE),"") -> Cash in Bank_BDO Unibank-DHPP | J11: 93550
C12: NOV. 1- 3, 2025 | E12: REFER TO COLLECTION SUMMARY | G12: COLLECTION OF PREVIOUS PAYMENTS DIRECTLY DEPOSITED TO E.TAN- STPC | H12: 15500 | I12: =IF(H12<>"",VLOOKUP(H12,ChartofAccountsTable,2,FALSE),"") -> Due from Other Cos. - DHPP | J12: 223952
C13: NOV. 1- 3, 2025 | E13: REFER TO COLLECTION SUMMARY | G13: TOTAL COLLECTIONS FOR THE WEEK- FVB CHECKING | H13: 10030 | I13: =IF(H13<>"",VLOOKUP(H13,ChartofAccountsTable,2,FALSE),"") -> Cash in Bank_1VB-DHPP | J13: 441150
C14: NOV. 1- 3, 2025 | E14: REFER TO COLLECTION SUMMARY | G14: TOTAL COLLECTIONS FOR THE WEEK- KB CHECKING | H14: 10060 | I14: =IF(H14<>"",VLOOKUP(H14,ChartofAccountsTable,2,FALSE),"") -> Cash in Bank_KB-DHPP | J14: 50000
C15: NOV. 1- 3, 2025 | E15: REFER TO COLLECTION SUMMARY | G15: TOTAL COLLECTIONS FOR THE WEEK- PSBC CHECKING | H15: 10110 | I15: =IF(H15<>"",VLOOKUP(H15,ChartofAccountsTable,2,FALSE),"") -> Cash in Bank_PSBC CHECKING-DHPP | J15: 0
C16: NOV. 1- 3, 2025 | E16: REFER TO COLLECTION SUMMARY | G16: TO RECOGNIZE RECEIVABLE FOR PAYMENTS DIRECTLY DEPOSITED THRU GCASH_CNR | H16: 12020 | I16: =IF(H16<>"",VLOOKUP(H16,ChartofAccountsTable,2,FALSE),"") -> A/Receivables - Other Current -DHPP | J16: 1500
C17: NOV. 1- 3, 2025 | E17: REFER TO COLLECTION SUMMARY | G17: TOTAL COLLECTIONS FOR THE WEEK- CASH ON HAND | H17: 10010 | I17: =IF(H17<>"",VLOOKUP(H17,ChartofAccountsTable,2,FALSE),"") -> Cash on Hand-DHPP | J17: 92725
C18: NOV. 1- 3, 2025 | E18: REFER TO COLLECTION SUMMARY | G18: TOTAL COLLECTIONS FROM PREVIOUS CYCLE | H18: 12030 | I18: =IF(H18<>"",VLOOKUP(H18,ChartofAccountsTable,2,FALSE),"") -> A/Receivables - Fuel Clients | K18: 286200
C19: NOV. 1- 3, 2025 | E19: REFER TO COLLECTION SUMMARY | G19: SET UP PAYABLES FROM COLLECTIONS OF PAYMENTS | H19: 21000 | I19: =IF(H19<>"",VLOOKUP(H19,ChartofAccountsTable,2,FALSE),"") -> Unearned Revenue - DHPP | K19: 1565625
I20: =IF(H20<>"",VLOOKUP(H20,ChartofAccountsTable,2,FALSE),"")
C21: NOV. 4-10, 2025 | E21: REFER TO COLLECTION SUMMARY | G21: TOTAL COLLECTIONS FOR THE WEEK-PNB CHECKING | H21: 10040 | I21: =IF(H21<>"",VLOOKUP(H21,ChartofAccountsTable,2,FALSE),"") -> Cash in Bank_PNB-DHPP | J21: 1544900
C22: NOV. 4-10, 2025 | E22: REFER TO COLLECTION SUMMARY | G22: TOTAL COLLECTIONS FOR THE WEEK-MBTC CHECKING | H22: 10080 | I22: =IF(H22<>"",VLOOKUP(H22,ChartofAccountsTable,2,FALSE),"") -> Cash in Bank_MBTC-DHPP | J22: 1881800
C23: NOV. 4-10, 2025 | E23: REFER TO COLLECTION SUMMARY | G23: TOTAL COLLECTIONS FOR THE WEEK-BDO CHECKING | H23: 10070 | I23: =IF(H23<>"",VLOOKUP(H23,ChartofAccountsTable,2,FALSE),"") -> Cash in Bank_BDO Unibank-DHPP | J23: 492190
C24: NOV. 4-10, 2025 | E24: REFER TO COLLECTION SUMMARY | G24: COLLECTION OF PREVIOUS PAYMENTS DIRECTLY DEPOSITED TO E.TAN- STPC | H24: 15500 | I24: =IF(H24<>"",VLOOKUP(H24,ChartofAccountsTable,2,FALSE),"") -> Due from Other Cos. - DHPP | J24: 481000
C25: NOV. 4-10, 2025 | E25: REFER TO COLLECTION SUMMARY | G25: TOTAL COLLECTIONS FOR THE WEEK- FVB CHECKING | H25: 10030 | I25: =IF(H25<>"",VLOOKUP(H25,ChartofAccountsTable,2,FALSE),"") -> Cash in Bank_1VB-DHPP | J25: 3349950
C26: NOV. 4-10, 2025 | E26: REFER TO COLLECTION SUMMARY | G26: TOTAL COLLECTIONS FOR THE WEEK- KB CHECKING | H26: 10060 | I26: =IF(H26<>"",VLOOKUP(H26,ChartofAccountsTable,2,FALSE),"") -> Cash in Bank_KB-DHPP | J26: 156900
C27: NOV. 4-10, 2025 | E27: REFER TO COLLECTION SUMMARY | G27: TOTAL COLLECTIONS FOR THE WEEK- PSBC CHECKING | H27: 10110 | I27: =IF(H27<>"",VLOOKUP(H27,ChartofAccountsTable,2,FALSE),"") -> Cash in Bank_PSBC CHECKING-DHPP | J27: 599325
C28: NOV. 4-10, 2025 | E28: REFER TO COLLECTION SUMMARY | G28: TO RECOGNIZE RECEIVABLE FOR PAYMENTS DIRECTLY DEPOSITED THRU GCASH_CNR | H28: 12020 | I28: =IF(H28<>"",VLOOKUP(H28,ChartofAccountsTable,2,FALSE),"") -> A/Receivables - Other Current -DHPP | J28: 38000
C29: NOV. 4-10, 2025 | E29: REFER TO COLLECTION SUMMARY | G29: TOTAL COLLECTIONS FOR THE WEEK- CASH ON HAND | H29: 10010 | I29: =IF(H29<>"",VLOOKUP(H29,ChartofAccountsTable,2,FALSE),"") -> Cash on Hand-DHPP | J29: 48075
C30: NOV. 4-10, 2025 | E30: REFER TO COLLECTION SUMMARY | G30: TOTAL COLLECTIONS FROM PREVIOUS CYCLE | H30: 12030 | I30: =IF(H30<>"",VLOOKUP(H30,ChartofAccountsTable,2,FALSE),"") -> A/Receivables - Fuel Clients | K30: 828575
C31: NOV. 4-10, 2025 | E31: REFER TO COLLECTION SUMMARY | G31: SET UP PAYABLES FROM COLLECTIONS OF PAYMENTS | H31: 21000 | I31: =IF(H31<>"",VLOOKUP(H31,ChartofAccountsTable,2,FALSE),"") -> Unearned Revenue - DHPP | K31: 7763565
I32: =IF(H32<>"",VLOOKUP(H32,ChartofAccountsTable,2,FALSE),"")
C33: NOV. 11- 17, 2025 | E33: REFER TO COLLECTION SUMMARY | G33: TOTAL COLLECTIONS FOR THE WEEK-PNB CHECKING | H33: 10040 | I33: =IF(H33<>"",VLOOKUP(H33,ChartofAccountsTable,2,FALSE),"") -> Cash in Bank_PNB-DHPP | J33: 2745400
C34: NOV. 11- 17, 2025 | E34: REFER TO COLLECTION SUMMARY | G34: TOTAL COLLECTIONS FOR THE WEEK-MBTC CHECKING | H34: 10080 | I34: =IF(H34<>"",VLOOKUP(H34,ChartofAccountsTable,2,FALSE),"") -> Cash in Bank_MBTC-DHPP | J34: 1591350
C35: NOV. 11- 17, 2025 | E35: REFER TO COLLECTION SUMMARY | G35: TOTAL COLLECTIONS FOR THE WEEK-BDO CHECKING | H35: 10070 | I35: =IF(H35<>"",VLOOKUP(H35,ChartofAccountsTable,2,FALSE),"") -> Cash in Bank_BDO Unibank-DHPP | J35: 429250
C36: NOV. 11- 17, 2025 | E36: REFER TO COLLECTION SUMMARY | G36: COLLECTION OF PREVIOUS PAYMENTS DIRECTLY DEPOSITED TO E.TAN- STPC | H36: 15500 | I36: =IF(H36<>"",VLOOKUP(H36,ChartofAccountsTable,2,FALSE),"") -> Due from Other Cos. - DHPP | J36: 560750
C37: NOV. 11- 17, 2025 | E37: REFER TO COLLECTION SUMMARY | G37: TOTAL COLLECTIONS FOR THE WEEK- FVB CHECKING | H37: 10030 | I37: =IF(H37<>"",VLOOKUP(H37,ChartofAccountsTable,2,FALSE),"") -> Cash in Bank_1VB-DHPP | J37: 3505395
C38: NOV. 11- 17, 2025 | E38: REFER TO COLLECTION SUMMARY | G38: TOTAL COLLECTIONS FOR THE WEEK- KB CHECKING | H38: 10060 | I38: =IF(H38<>"",VLOOKUP(H38,ChartofAccountsTable,2,FALSE),"") -> Cash in Bank_KB-DHPP | J38: 105300
C39: NOV. 11- 17, 2025 | E39: REFER TO COLLECTION SUMMARY | G39: TOTAL COLLECTIONS FOR THE WEEK- PSBC CHECKING | H39: 10110 | I39: =IF(H39<>"",VLOOKUP(H39,ChartofAccountsTable,2,FALSE),"") -> Cash in Bank_PSBC CHECKING-DHPP | J39: 407000
C40: NOV. 11- 17, 2025 | E40: REFER TO COLLECTION SUMMARY | G40: TO RECOGNIZE RECEIVABLE FOR PAYMENTS DIRECTLY DEPOSITED THRU GCASH_CNR | H40: 12020 | I40: =IF(H40<>"",VLOOKUP(H40,ChartofAccountsTable,2,FALSE),"") -> A/Receivables - Other Current -DHPP | J40: 46025
C41: NOV. 11- 17, 2025 | E41: REFER TO COLLECTION SUMMARY | G41: TOTAL COLLECTIONS FOR THE WEEK- CASH ON HAND | H41: 10010 | I41: =IF(H41<>"",VLOOKUP(H41,ChartofAccountsTable,2,FALSE),"") -> Cash on Hand-DHPP | K41: 86675
...

Sheet FUEL INVENTORY
B2: GENERAL JOURNAL FOR FUEL PICKED UP AND DELIVERY TO CLIENTS (SUPPLIER)
D3: ATL
B4: Data last entry date | D4: CN | F4: =MAX(B9:B205) -> 0
D5: WC | K5: =K6-J6 -> 0
D6: DR | I6: 5100 | J6: =SUBTOTAL(9,J9:J920000) -> 0 | K6: =SUBTOTAL(9,K9:K920000) -> 0
B7: Pick Up Date | C7: PAYMENT REF / Supplier Ref. | D7: ATL /CN/DR/WC | E7: NUMBER | F7: PAYMENT CYCLE FROM | G7: Description | H7: CoA | I7: Account Name | J7: Debit | K7: Credit
J8: =IF(SUM(J9:J205)=SUM(K9:K205),"Balance","Not Balance") -> Balance
I9: =IF(H9<>"",VLOOKUP(H9,ChartofAccountsTable,2,FALSE),"")
I10: =IF(H10<>"",VLOOKUP(H10,ChartofAccountsTable,2,FALSE),"")
I11: =IF(H11<>"",VLOOKUP(H11,ChartofAccountsTable,2,FALSE),"")
I12: =IF(H12<>"",VLOOKUP(H12,ChartofAccountsTable,2,FALSE),"")
I13: =IF(H13<>"",VLOOKUP(H13,ChartofAccountsTable,2,FALSE),"")
I14: =IF(H14<>"",VLOOKUP(H14,ChartofAccountsTable,2,FALSE),"")
I15: =IF(H15<>"",VLOOKUP(H15,ChartofAccountsTable,2,FALSE),"")
I16: =IF(H16<>"",VLOOKUP(H16,ChartofAccountsTable,2,FALSE),"")
I17: =IF(H17<>"",VLOOKUP(H17,ChartofAccountsTable,2,FALSE),"")
I18: =IF(H18<>"",VLOOKUP(H18,ChartofAccountsTable,2,FALSE),"")
I19: =IF(H19<>"",VLOOKUP(H19,ChartofAccountsTable,2,FALSE),"")
I20: =IF(H20<>"",VLOOKUP(H20,ChartofAccountsTable,2,FALSE),"")
... I205: =IF(H205<>"",VLOOKUP(H205,ChartofAccountsTable,2,FALSE),"")

Sheet AR-SUPPLIER
B2: GENERAL JOURNAL FOR PAYMETS TO DEPOT (SUPPLIER OF FUEL)
B4: Data last entry date | D4: =MAX(B8:B206) -> 0 | G4: 1110 | J4: =I5-J5 -> 0
F5: =SUM(F8:F59) -> 0 | G5: 1260 | I5: =SUBTOTAL(9,I8:I20000) -> 0 | J5: =SUBTOTAL(9,J8:J20000) -> 0
B6: Date | C6: Supplier / Bank | D6: PAYMENT CYCLE | E6: Description | F6: Volume (in KL) | G6: CoA | H6: Account Name | I6: Debit | J6: Credit
I7: =IF(SUM(I8:I206)=SUM(J8:J206),"Balance","Not Balance") -> Balance
H8: =IF(G8<>"",VLOOKUP(G8,ChartofAccountsTable,2,FALSE),"")
H9: =IF(G9<>"",VLOOKUP(G9,ChartofAccountsTable,2,FALSE),"")
H10: =IF(G10<>"",VLOOKUP(G10,ChartofAccountsTable,2,FALSE),"")
H11: =IF(G11<>"",VLOOKUP(G11,ChartofAccountsTable,2,FALSE),"")
H12: =IF(G12<>"",VLOOKUP(G12,ChartofAccountsTable,2,FALSE),"")
H13: =IF(G13<>"",VLOOKUP(G13,ChartofAccountsTable,2,FALSE),"")
H14: =IF(G14<>"",VLOOKUP(G14,ChartofAccountsTable,2,FALSE),"")
H15: =IF(G15<>"",VLOOKUP(G15,ChartofAccountsTable,2,FALSE),"")
H16: =IF(G16<>"",VLOOKUP(G16,ChartofAccountsTable,2,FALSE),"")
H17: =IF(G17<>"",VLOOKUP(G17,ChartofAccountsTable,2,FALSE),"")
H18: =IF(G18<>"",VLOOKUP(G18,ChartofAccountsTable,2,FALSE),"")
H19: =IF(G19<>"",VLOOKUP(G19,ChartofAccountsTable,2,FALSE),"")
... H206: =IF(G206<>"",VLOOKUP(G206,ChartofAccountsTable,2,FALSE),"")
B207: © 2017 - ExcelTemplate.NET

Sheet Copyright-2
A40: Need help? Please see this page for information:
A41: https://exceltemplate.net/support/

Sheet UPON DELIVERY
B1: JAN 1-30, 2026
B2: ='PAYMENT RECEIPTS'!B2 -> DISTRIBUTION AND HAULING OF PETROLEUM PRODUCTS
B3: GENERAL JOURNAL FOR RECOGNITION OF SALES
B5: Data last entry date | G5: =MAX(B131:B1291) -> 46049 | N5: =N6-M6 -> 0
M6: =SUBTOTAL(9,M9:M820167) -> 24141215 | N6: =SUBTOTAL(9,N9:N820167) -> 24141215
B7: Delivery Date | C7: Bank / Dr. No | D7: ACKNOWLEDGMENT RECEIPT # | E7: PO # | F7: Order / Payment Cycle | G7: Supplier/Customer Code | H7: Description | I7: NO OF ORDERS | J7: TANKER | K7: CoA | L7: Account Name | M7: Debit | N7: Credit
M8: =IF(SUM(M9:M194)=SUM(N9:N194),"Balance","Not Balance") -> Balance
B9: 46025 | C9: 1156 | D9: 53113 | E9: 12e 3331 p | F9: DEC.30- JAN. 5, 2026 | G9: Claritas | H9: 1000 X 0 R 0 D | I9: 1 | J9: MAW 7645 | K9: 21000 | L9: =IF(K9<>"",VLOOKUP(K9,ChartofAccountsTable,2,FALSE),"") -> Unearned Revenue - DHPP | M9: 51800
J10: MAW 7645 | K10: 40000 | L10: =IF(K10<>"",VLOOKUP(K10,ChartofAccountsTable,2,FALSE),"") -> Sales -Fuel Hauling | N10: 51800
B11: 46025 | C11: 1157 | E11: 12e 3313 p | G11: Villaflor Aya G | H11: 1000 X 0 R 0 D | I11: 1 | J11: MAW 7645 | K11: 21000 | L11: =IF(K11<>"",VLOOKUP(K11,ChartofAccountsTable,2,FALSE),"") -> Unearned Revenue - DHPP | M11: 51950
J12: MAW 7645 | K12: 40000 | L12: =IF(K12<>"",VLOOKUP(K12,ChartofAccountsTable,2,FALSE),"") -> Sales -Fuel Hauling | N12: 51950
B13: 46025 | C13: 1159 | E13: 12e 3327 p | G13: Villaflor Len | H13: 1000 X 0 R 0 D | I13: 1 | J13: MAW 7645 | K13: 21000 | L13: =IF(K13<>"",VLOOKUP(K13,ChartofAccountsTable,2,FALSE),"") -> Unearned Revenue - DHPP | M13: 51950
J14: MAW 7645 | K14: 40000 | L14: =IF(K14<>"",VLOOKUP(K14,ChartofAccountsTable,2,FALSE),"") -> Sales -Fuel Hauling | N14: 51950
B15: 46025 | C15: 1159 | E15: 12e 3276_b p | G15: Villaflor Len | H15: 1000 X 0 R 0 D | I15: 1 | J15: MAW 7645 | K15: 21000 | L15: =IF(K15<>"",VLOOKUP(K15,ChartofAccountsTable,2,FALSE),"") -> Unearned Revenue - DHPP | M15: 102400 | O15: OVERPAYMENT FROM DEC. 23-29
J16: MAW 7645 | K16: 40000 | L16: =IF(K16<>"",VLOOKUP(K16,ChartofAccountsTable,2,FALSE),"") -> Sales -Fuel Hauling | N16: 102400
B17: 46026 | C17: 1160 | E17: 12e 3351 | G17: San Pedro B. | H17: 0 X 500 R 0 D | I17: 0.5 | J17: MAW 7645 | K17: 21000 | L17: =IF(K17<>"",VLOOKUP(K17,ChartofAccountsTable,2,FALSE),"") -> Unearned Revenue - DHPP | M17: 24450
J18: MAW 7645 | K18: 40000 | L18: =IF(K18<>"",VLOOKUP(K18,ChartofAccountsTable,2,FALSE),"") -> Sales -Fuel Hauling | N18: 24450
B19: 46026 | C19: 1161 | E19: 12e 3318 p | G19: Napo | H19: 0 X 0 R 500 D | I19: 0.5 | J19: MAW 7645 | K19: 21000 | L19: =IF(K19<>"",VLOOKUP(K19,ChartofAccountsTable,2,FALSE),"") -> Unearned Revenue - DHPP | M19: 51900
J20: MAW 7645 | K20: 12030 | L20: =IF(K20<>"",VLOOKUP(K20,ChartofAccountsTable,2,FALSE),"") -> A/Receivables - Fuel Clients | M20: 200
J21: MAW 7645 | K21: 40000 | L21: =IF(K21<>"",VLOOKUP(K21,ChartofAccountsTable,2,FALSE),"") -> Sales -Fuel Hauling | N21: 52100
B22: 46027 | C22: 1162 | E22: 12e 3308_b | G22: Tabon | H22: 1000 X 0 R 0 D | I22: 1 | J22: MAM 2369 | K22: 21000 | L22: =IF(K22<>"",VLOOKUP(K22,ChartofAccountsTable,2,FALSE),"") -> Unearned Revenue - DHPP | M22: 24725
J23: MAM 2369 | K23: 12030 | L23: =IF(K23<>"",VLOOKUP(K23,ChartofAccountsTable,2,FALSE),"") -> A/Receivables - Fuel Clients | M23: 24725
J24: MAM 2369 | K24: 40000 | L24: =IF(K24<>"",VLOOKUP(K24,ChartofAccountsTable,2,FALSE),"") -> Sales -Fuel Hauling | N24: 49450
B25: 46027 | C25: 1163 | E25: 12e 3288_a p | G25: Siari | H25: 500 X 0 R 0 D | I25: 0.5 | J25: MAM 2369 | K25: 21000 | L25: =IF(K25<>"",VLOOKUP(K25,ChartofAccountsTable,2,FALSE),"") -> Unearned Revenue - DHPP | M25: 102650
J26: MAM 2369 | K26: 12030 | L26: =IF(K26<>"",VLOOKUP(K26,ChartofAccountsTable,2,FALSE),"") -> A/Receivables - Fuel Clients | M26: 150 | O26: OVERPAYMENT ON DEC.23-29 2025
J27: MAM 2369 | K27: 40000 | L27: =IF(K27<>"",VLOOKUP(K27,ChartofAccountsTable,2,FALSE),"") -> Sales -Fuel Hauling | N27: 102800
B28: 46027 | C28: 1163 | E28: 12e 3349 p | G28: Siari | H28: 500 X 0 R 0 D | I28: 0.5 | J28: MAM 2369 | K28: 21000 | L28: =IF(K28<>"",VLOOKUP(K28,ChartofAccountsTable,2,FALSE),"") -> Unearned Revenue - DHPP | M28: 51400
J29: MAM 2369 | K29: 40000 | L29: =IF(K29<>"",VLOOKUP(K29,ChartofAccountsTable,2,FALSE),"") -> Sales -Fuel Hauling | N29: 51400
B30: 46025 | C30: 525 | E30: 12e 3299 p | G30: Tudela | H30: 1000 X 500 R 0 D | I30: 1.5 | J30: KAP 8160 | K30: 21000 | L30: =IF(K30<>"",VLOOKUP(K30,ChartofAccountsTable,2,FALSE),"") -> Unearned Revenue - DHPP | M30: 500000
J31: KAP 8160 | K31: 40000 | L31: =IF(K31<>"",VLOOKUP(K31,ChartofAccountsTable,2,FALSE),"") -> Sales -Fuel Hauling | N31: 500000
B32: 46025 | C32: 895 | E32: 12e 3350 | G32: San Pedro B. | H32: 2000 X 500 R 0 D | I32: 2.5 | J32: KAP 8160 | K32: 12030 | L32: =IF(K32<>"",VLOOKUP(K32,ChartofAccountsTable,2,FALSE),"") -> A/Receivables - Fuel Clients | M32: 120750
J33: KAP 8160 | K33: 40000 | L33: =IF(K33<>"",VLOOKUP(K33,ChartofAccountsTable,2,FALSE),"") -> Sales -Fuel Hauling | N33: 120750
B34: 46026 | C34: 900 | E34: 12e 3328_a | G34: Del Pilar | H34: 0 X 500 R 500 D | I34: 1 | J34: KAP 8160 | K34: 21000 | L34: =IF(K34<>"",VLOOKUP(K34,ChartofAccountsTable,2,FALSE),"") -> Unearned Revenue - DHPP | M34: 26050
J35: KAP 8160 | K35: 12030 | L35: =IF(K35<>"",VLOOKUP(K35,ChartofAccountsTable,2,FALSE),"") -> A/Receivables - Fuel Clients | M35: 26000
J36: KAP 8160 | K36: 40000 | L36: =IF(K36<>"",VLOOKUP(K36,ChartofAccountsTable,2,FALSE),"") -> Sales -Fuel Hauling | N36: 52050
B37: 46027 | C37: 901 | E37: 1a 3372 Adv | G37: San Pedro | H37: 2000 X 0 R 0 D | I37: 2 | J37: KAP 8160 | K37: 12030 | L37: =IF(K37<>"",VLOOKUP(K37,ChartofAccountsTable,2,FALSE),"") -> A/Receivables - Fuel Clients | M37: 24600
J38: KAP 8160 | K38: 40000 | L38: =IF(K38<>"",VLOOKUP(K38,ChartofAccountsTable,2,FALSE),"") -> Sales -Fuel Hauling | N38: 24600
B39: 46026 | C39: 899 | E39: 12e 3346 p | G39: Don Vic Dennis | H39: 1000 X 0 R 500 D | I39: 1.5 | J39: KAP 8160 | K39: 21000 | L39: =IF(K39<>"",VLOOKUP(K39,ChartofAccountsTable,2,FALSE),"") -> Unearned Revenue - DHPP | M39: 52050
J40: KAP 8160 | K40: 40000 | L40: =IF(K40<>"",VLOOKUP(K40,ChartofAccountsTable,2,FALSE),"") -> Sales -Fuel Hauling | N40: 52050
B41: 46026 | C41: 896 | E41: 12e 3279_b | G41: Guitran | H41: 0 X 500 R 0 D | I41: 0.5 | J41: KAP 8160 | K41: 21000 | L41: =IF(K41<>"",VLOOKUP(K41,ChartofAccountsTable,2,FALSE),"") -> Unearned Revenue - DHPP | M41: 153700
...

Sheet JOURNAL ENTRY
A3: See this link: | B3: Acctg Entry - finance and acctg..xlsx

Sheet SUPPLIER CODE
A1: SUPPLIER CODE
A2: MTHSI
A3: INVTY
A4: INVTY-DOH
A5: INVTY-OFFICE
A6: Aseniero
A7: Bacong Bulilit
A8: Bacong Pamil
A9: Bago
A10: Bagumbang Palomar
A11: Bajo Oroqueita
A12: Balagon Siay
... A121: Tigbao GWEN
